2024-10-24T13:31:25.771734367Z W1024 13:31:25.771609       1 feature_gate.go:330] unrecognized feature gate: PlatformOperators
2024-10-24T13:31:25.771915637Z W1024 13:31:25.771863       1 feature_gate.go:330] unrecognized feature gate: AdminNetworkPolicy
2024-10-24T13:31:25.771915637Z W1024 13:31:25.771878       1 feature_gate.go:330] unrecognized feature gate: AWSEFSDriverVolumeMetrics
2024-10-24T13:31:25.771915637Z W1024 13:31:25.771882       1 feature_gate.go:330] unrecognized feature gate: CSIDriverSharedResource
2024-10-24T13:31:25.771915637Z W1024 13:31:25.771894       1 feature_gate.go:330] unrecognized feature gate: MixedCPUsAllocation
2024-10-24T13:31:25.771915637Z W1024 13:31:25.771899       1 feature_gate.go:330] unrecognized feature gate: BootcNodeManagement
2024-10-24T13:31:25.771915637Z W1024 13:31:25.771902       1 feature_gate.go:330] unrecognized feature gate: ClusterAPIInstall
2024-10-24T13:31:25.771915637Z W1024 13:31:25.771907       1 feature_gate.go:330] unrecognized feature gate: ExternalOIDC
2024-10-24T13:31:25.771915637Z W1024 13:31:25.771910       1 feature_gate.go:330] unrecognized feature gate: MachineAPIOperatorDisableMachineHealthCheckController
2024-10-24T13:31:25.771958037Z W1024 13:31:25.771914       1 feature_gate.go:330] unrecognized feature gate: NewOLM
2024-10-24T13:31:25.771958037Z W1024 13:31:25.771919       1 feature_gate.go:330] unrecognized feature gate: GatewayAPI
2024-10-24T13:31:25.771958037Z W1024 13:31:25.771924       1 feature_gate.go:353] Setting GA feature gate CloudDualStackNodeIPs=true. It will be removed in a future release.
2024-10-24T13:31:25.771958037Z W1024 13:31:25.771928       1 feature_gate.go:330] unrecognized feature gate: BuildCSIVolumes
2024-10-24T13:31:25.771958037Z W1024 13:31:25.771932       1 feature_gate.go:330] unrecognized feature gate: InsightsConfig
2024-10-24T13:31:25.771958037Z W1024 13:31:25.771936       1 feature_gate.go:330] unrecognized feature gate: PersistentIPsForVirtualization
2024-10-24T13:31:25.771958037Z W1024 13:31:25.771940       1 feature_gate.go:330] unrecognized feature gate: MachineAPIProviderOpenStack
2024-10-24T13:31:25.771958037Z W1024 13:31:25.771944       1 feature_gate.go:330] unrecognized feature gate: ClusterAPIInstallIBMCloud
2024-10-24T13:31:25.771958037Z W1024 13:31:25.771948       1 feature_gate.go:330] unrecognized feature gate: NetworkLiveMigration
2024-10-24T13:31:25.771958037Z W1024 13:31:25.771952       1 feature_gate.go:330] unrecognized feature gate: AlibabaPlatform
2024-10-24T13:31:25.771971777Z W1024 13:31:25.771955       1 feature_gate.go:330] unrecognized feature gate: OVNObservability
2024-10-24T13:31:25.771971777Z W1024 13:31:25.771960       1 feature_gate.go:330] unrecognized feature gate: OnClusterBuild
2024-10-24T13:31:25.771971777Z W1024 13:31:25.771964       1 feature_gate.go:330] unrecognized feature gate: ManagedBootImagesAWS
2024-10-24T13:31:25.771971777Z W1024 13:31:25.771967       1 feature_gate.go:330] unrecognized feature gate: ChunkSizeMiB
2024-10-24T13:31:25.771983777Z W1024 13:31:25.771970       1 feature_gate.go:330] unrecognized feature gate: PinnedImages
2024-10-24T13:31:25.771983777Z W1024 13:31:25.771974       1 feature_gate.go:330] unrecognized feature gate: SigstoreImageVerification
2024-10-24T13:31:25.771983777Z W1024 13:31:25.771977       1 feature_gate.go:330] unrecognized feature gate: MetricsServer
2024-10-24T13:31:25.771983777Z W1024 13:31:25.771980       1 feature_gate.go:330] unrecognized feature gate: VSphereMultiVCenters
2024-10-24T13:31:25.771993837Z W1024 13:31:25.771984       1 feature_gate.go:330] unrecognized feature gate: BareMetalLoadBalancer
2024-10-24T13:31:25.771993837Z W1024 13:31:25.771987       1 feature_gate.go:330] unrecognized feature gate: InsightsRuntimeExtractor
2024-10-24T13:31:25.772023417Z W1024 13:31:25.771992       1 feature_gate.go:353] Setting GA feature gate DisableKubeletCloudCredentialProviders=true. It will be removed in a future release.
2024-10-24T13:31:25.772023417Z W1024 13:31:25.771998       1 feature_gate.go:330] unrecognized feature gate: MultiArchInstallGCP
2024-10-24T13:31:25.772023417Z W1024 13:31:25.772002       1 feature_gate.go:330] unrecognized feature gate: HardwareSpeed
2024-10-24T13:31:25.772023417Z W1024 13:31:25.772007       1 feature_gate.go:330] unrecognized feature gate: InsightsConfigAPI
2024-10-24T13:31:25.772023417Z W1024 13:31:25.772010       1 feature_gate.go:330] unrecognized feature gate: GCPClusterHostedDNS
2024-10-24T13:31:25.772023417Z W1024 13:31:25.772014       1 feature_gate.go:330] unrecognized feature gate: NodeDisruptionPolicy
2024-10-24T13:31:25.772023417Z W1024 13:31:25.772017       1 feature_gate.go:330] unrecognized feature gate: ManagedBootImages
2024-10-24T13:31:25.772023417Z W1024 13:31:25.772020       1 feature_gate.go:330] unrecognized feature gate: VolumeGroupSnapshot
2024-10-24T13:31:25.772057297Z W1024 13:31:25.772034       1 feature_gate.go:330] unrecognized feature gate: PrivateHostedZoneAWS
2024-10-24T13:31:25.772091937Z W1024 13:31:25.772080       1 feature_gate.go:330] unrecognized feature gate: UpgradeStatus
2024-10-24T13:31:25.772117787Z W1024 13:31:25.772107       1 feature_gate.go:330] unrecognized feature gate: IngressControllerDynamicConfigurationManager
2024-10-24T13:31:25.772143097Z W1024 13:31:25.772133       1 feature_gate.go:330] unrecognized feature gate: GCPLabelsTags
2024-10-24T13:31:25.772176987Z W1024 13:31:25.772166       1 feature_gate.go:330] unrecognized feature gate: AzureWorkloadIdentity
2024-10-24T13:31:25.772201347Z W1024 13:31:25.772191       1 feature_gate.go:330] unrecognized feature gate: VSphereStaticIPs
2024-10-24T13:31:25.772224767Z W1024 13:31:25.772215       1 feature_gate.go:330] unrecognized feature gate: AWSClusterHostedDNS
2024-10-24T13:31:25.772248387Z W1024 13:31:25.772238       1 feature_gate.go:330] unrecognized feature gate: MultiArchInstallAWS
2024-10-24T13:31:25.772271917Z W1024 13:31:25.772262       1 feature_gate.go:330] unrecognized feature gate: Example
2024-10-24T13:31:25.772297667Z W1024 13:31:25.772288       1 feature_gate.go:330] unrecognized feature gate: NetworkSegmentation
2024-10-24T13:31:25.772321347Z W1024 13:31:25.772311       1 feature_gate.go:330] unrecognized feature gate: AdditionalRoutingCapabilities
2024-10-24T13:31:25.772362407Z W1024 13:31:25.772351       1 feature_gate.go:330] unrecognized feature gate: AutomatedEtcdBackup
2024-10-24T13:31:25.772386037Z W1024 13:31:25.772376       1 feature_gate.go:330] unrecognized feature gate: NetworkDiagnosticsConfig
2024-10-24T13:31:25.772410767Z W1024 13:31:25.772400       1 feature_gate.go:330] unrecognized feature gate: InsightsOnDemandDataGather
2024-10-24T13:31:25.772437437Z W1024 13:31:25.772427       1 feature_gate.go:351] Setting deprecated feature gate KMSv1=true. It will be removed in a future release.
2024-10-24T13:31:25.772462077Z W1024 13:31:25.772452       1 feature_gate.go:330] unrecognized feature gate: DNSNameResolver
2024-10-24T13:31:25.772485837Z W1024 13:31:25.772476       1 feature_gate.go:330] unrecognized feature gate: SetEIPForNLBIngressController
2024-10-24T13:31:25.772509167Z W1024 13:31:25.772499       1 feature_gate.go:330] unrecognized feature gate: EtcdBackendQuota
2024-10-24T13:31:25.772533197Z W1024 13:31:25.772523       1 feature_gate.go:330] unrecognized feature gate: VSphereDriverConfiguration
2024-10-24T13:31:25.772556387Z W1024 13:31:25.772547       1 feature_gate.go:330] unrecognized feature gate: MultiArchInstallAzure
2024-10-24T13:31:25.772588767Z W1024 13:31:25.772578       1 feature_gate.go:330] unrecognized feature gate: SignatureStores
2024-10-24T13:31:25.772614287Z W1024 13:31:25.772604       1 feature_gate.go:330] unrecognized feature gate: MachineConfigNodes
2024-10-24T13:31:25.772637887Z W1024 13:31:25.772628       1 feature_gate.go:330] unrecognized feature gate: ClusterMonitoringConfig
2024-10-24T13:31:25.772661487Z W1024 13:31:25.772651       1 feature_gate.go:330] unrecognized feature gate: OpenShiftPodSecurityAdmission
2024-10-24T13:31:25.772685077Z W1024 13:31:25.772675       1 feature_gate.go:330] unrecognized feature gate: VSphereControlPlaneMachineSet
2024-10-24T13:31:25.772710727Z W1024 13:31:25.772701       1 feature_gate.go:353] Setting GA feature gate ValidatingAdmissionPolicy=true. It will be removed in a future release.
2024-10-24T13:31:25.772738097Z W1024 13:31:25.772726       1 feature_gate.go:330] unrecognized feature gate: MetricsCollectionProfiles
2024-10-24T13:31:25.772803697Z W1024 13:31:25.772788       1 feature_gate.go:330] unrecognized feature gate: VSphereMultiNetworks
2024-10-24T13:31:25.772841197Z W1024 13:31:25.772829       1 feature_gate.go:330] unrecognized feature gate: MachineAPIMigration
2024-10-24T13:31:25.772868717Z W1024 13:31:25.772858       1 feature_gate.go:330] unrecognized feature gate: IngressControllerLBSubnetsAWS
2024-10-24T13:31:25.772893707Z W1024 13:31:25.772884       1 feature_gate.go:330] unrecognized feature gate: RouteAdvertisements
2024-10-24T13:31:25.772917357Z W1024 13:31:25.772908       1 feature_gate.go:330] unrecognized feature gate: ImageStreamImportMode
2024-10-24T13:31:25.773052737Z I1024 13:31:25.773032       1 flags.go:64] FLAG: --allow-metric-labels="[]"
2024-10-24T13:31:25.773085847Z I1024 13:31:25.773072       1 flags.go:64] FLAG: --allow-metric-labels-manifest=""
2024-10-24T13:31:25.773116617Z I1024 13:31:25.773103       1 flags.go:64] FLAG: --authentication-kubeconfig="/etc/kubernetes/static-pod-resources/configmaps/scheduler-kubeconfig/kubeconfig"
2024-10-24T13:31:25.773145587Z I1024 13:31:25.773133       1 flags.go:64] FLAG: --authentication-skip-lookup="false"
2024-10-24T13:31:25.773184927Z I1024 13:31:25.773171       1 flags.go:64] FLAG: --authentication-token-webhook-cache-ttl="10s"
2024-10-24T13:31:25.773210927Z I1024 13:31:25.773200       1 flags.go:64] FLAG: --authentication-tolerate-lookup-failure="true"
2024-10-24T13:31:25.773241027Z I1024 13:31:25.773225       1 flags.go:64] FLAG: --authorization-always-allow-paths="[/healthz,/readyz,/livez]"
2024-10-24T13:31:25.773267657Z I1024 13:31:25.773256       1 flags.go:64] FLAG: --authorization-kubeconfig="/etc/kubernetes/static-pod-resources/configmaps/scheduler-kubeconfig/kubeconfig"
2024-10-24T13:31:25.773292567Z I1024 13:31:25.773282       1 flags.go:64] FLAG: --authorization-webhook-cache-authorized-ttl="10s"
2024-10-24T13:31:25.773317137Z I1024 13:31:25.773306       1 flags.go:64] FLAG: --authorization-webhook-cache-unauthorized-ttl="10s"
2024-10-24T13:31:25.773343867Z I1024 13:31:25.773331       1 flags.go:64] FLAG: --bind-address="0.0.0.0"
2024-10-24T13:31:25.773368927Z I1024 13:31:25.773358       1 flags.go:64] FLAG: --cert-dir="/var/run/kubernetes"
2024-10-24T13:31:25.773393427Z I1024 13:31:25.773383       1 flags.go:64] FLAG: --client-ca-file=""
2024-10-24T13:31:25.773420497Z I1024 13:31:25.773408       1 flags.go:64] FLAG: --config="/etc/kubernetes/static-pod-resources/configmaps/config/config.yaml"
2024-10-24T13:31:25.773445897Z I1024 13:31:25.773435       1 flags.go:64] FLAG: --contention-profiling="true"
2024-10-24T13:31:25.773478757Z I1024 13:31:25.773468       1 flags.go:64] FLAG: --disable-http2-serving="false"
2024-10-24T13:31:25.773505847Z I1024 13:31:25.773493       1 flags.go:64] FLAG: --disabled-metrics="[]"
2024-10-24T13:31:25.773576517Z I1024 13:31:25.773555       1 flags.go:64] FLAG: --emulated-version="[]"
2024-10-24T13:31:25.773674117Z I1024 13:31:25.773594       1 flags.go:64] FLAG: --feature-gates=":AWSClusterHostedDNS=false,:AWSEFSDriverVolumeMetrics=true,:AdditionalRoutingCapabilities=false,:AdminNetworkPolicy=true,:AlibabaPlatform=true,:AutomatedEtcdBackup=false,:AzureWorkloadIdentity=true,:BareMetalLoadBalancer=true,:BootcNodeManagement=false,:BuildCSIVolumes=true,:CSIDriverSharedResource=false,:ChunkSizeMiB=true,:CloudDualStackNodeIPs=true,:ClusterAPIInstall=false,:ClusterAPIInstallIBMCloud=false,:ClusterMonitoringConfig=false,:DNSNameResolver=false,:DisableKubeletCloudCredentialProviders=true,:DynamicResourceAllocation=false,:EtcdBackendQuota=false,:EventedPLEG=false,:Example=false,:ExternalOIDC=false,:GCPClusterHostedDNS=false,:GCPLabelsTags=true,:GatewayAPI=false,:HardwareSpeed=true,:ImageStreamImportMode=false,:IngressControllerDynamicConfigurationManager=false,:IngressControllerLBSubnetsAWS=true,:InsightsConfig=false,:InsightsConfigAPI=false,:InsightsOnDemandDataGather=false,:InsightsRuntimeExtractor=false,:KMSv1=true,:MachineAPIMigration=false,:MachineAPIOperatorDisableMachineHealthCheckController=false,:MachineAPIProviderOpenStack=false,:MachineConfigNodes=false,:ManagedBootImages=true,:ManagedBootImagesAWS=false,:MaxUnavailableStatefulSet=false,:MetricsCollectionProfiles=false,:MetricsServer=true,:MixedCPUsAllocation=false,:MultiArchInstallAWS=true,:MultiArchInstallAzure=false,:MultiArchInstallGCP=true,:NetworkDiagnosticsConfig=true,:NetworkLiveMigration=true,:NetworkSegmentation=false,:NewOLM=false,:NodeDisruptionPolicy=true,:NodeSwap=false,:OVNObservability=false,:OnClusterBuild=false,:OpenShiftPodSecurityAdmission=true,:PersistentIPsForVirtualization=false,:PinnedImages=false,:PlatformOperators=false,:PrivateHostedZoneAWS=true,:ProcMountType=false,:RouteAdvertisements=false,:RouteExternalCertificate=false,:ServiceAccountTokenNodeBinding=false,:SetEIPForNLBIngressController=true,:SignatureStores=false,:SigstoreImageVerification=false,:TranslateStreamCloseWebsocketRequests=false,:UpgradeStatus=false,:UserNamespacesPodSecurityStandards=false,:UserNamespacesSupport=false,:VSphereControlPlaneMachineSet=true,:VSphereDriverConfiguration=true,:VSphereMultiNetworks=false,:VSphereMultiVCenters=false,:VSphereStaticIPs=true,:ValidatingAdmissionPolicy=true,:VolumeGroupSnapshot=false"
2024-10-24T13:31:25.773706937Z I1024 13:31:25.773694       1 flags.go:64] FLAG: --help="false"
2024-10-24T13:31:25.773742747Z I1024 13:31:25.773723       1 flags.go:64] FLAG: --http2-max-streams-per-connection="0"
2024-10-24T13:31:25.773790987Z I1024 13:31:25.773775       1 flags.go:64] FLAG: --kube-api-burst="100"
2024-10-24T13:31:25.773825307Z I1024 13:31:25.773812       1 flags.go:64] FLAG: --kube-api-content-type="application/vnd.kubernetes.protobuf"
2024-10-24T13:31:25.773853977Z I1024 13:31:25.773841       1 flags.go:64] FLAG: --kube-api-qps="50"
2024-10-24T13:31:25.773880897Z I1024 13:31:25.773870       1 flags.go:64] FLAG: --kubeconfig=""
2024-10-24T13:31:25.773907587Z I1024 13:31:25.773896       1 flags.go:64] FLAG: --leader-elect="true"
2024-10-24T13:31:25.773934177Z I1024 13:31:25.773923       1 flags.go:64] FLAG: --leader-elect-lease-duration="15s"
2024-10-24T13:31:25.773959397Z I1024 13:31:25.773949       1 flags.go:64] FLAG: --leader-elect-renew-deadline="10s"
2024-10-24T13:31:25.773984277Z I1024 13:31:25.773974       1 flags.go:64] FLAG: --leader-elect-resource-lock="leases"
2024-10-24T13:31:25.774008737Z I1024 13:31:25.773998       1 flags.go:64] FLAG: --leader-elect-resource-name="kube-scheduler"
2024-10-24T13:31:25.774042427Z I1024 13:31:25.774030       1 flags.go:64] FLAG: --leader-elect-resource-namespace="kube-system"
2024-10-24T13:31:25.774067907Z I1024 13:31:25.774057       1 flags.go:64] FLAG: --leader-elect-retry-period="2s"
2024-10-24T13:31:25.774092217Z I1024 13:31:25.774082       1 flags.go:64] FLAG: --log-flush-frequency="5s"
2024-10-24T13:31:25.774128387Z I1024 13:31:25.774107       1 flags.go:64] FLAG: --log-json-info-buffer-size="0"
2024-10-24T13:31:25.774161627Z I1024 13:31:25.774143       1 flags.go:64] FLAG: --log-json-split-stream="false"
2024-10-24T13:31:25.774188797Z I1024 13:31:25.774177       1 flags.go:64] FLAG: --log-text-info-buffer-size="0"
2024-10-24T13:31:25.774213407Z I1024 13:31:25.774203       1 flags.go:64] FLAG: --log-text-split-stream="false"
2024-10-24T13:31:25.774237317Z I1024 13:31:25.774227       1 flags.go:64] FLAG: --logging-format="text"
2024-10-24T13:31:25.774261507Z I1024 13:31:25.774251       1 flags.go:64] FLAG: --master=""
2024-10-24T13:31:25.774285397Z I1024 13:31:25.774275       1 flags.go:64] FLAG: --permit-address-sharing="false"
2024-10-24T13:31:25.774311857Z I1024 13:31:25.774301       1 flags.go:64] FLAG: --permit-port-sharing="false"
2024-10-24T13:31:25.774337007Z I1024 13:31:25.774326       1 flags.go:64] FLAG: --pod-max-in-unschedulable-pods-duration="5m0s"
2024-10-24T13:31:25.774361677Z I1024 13:31:25.774351       1 flags.go:64] FLAG: --profiling="true"
2024-10-24T13:31:25.774387627Z I1024 13:31:25.774375       1 flags.go:64] FLAG: --requestheader-allowed-names="[]"
2024-10-24T13:31:25.774413507Z I1024 13:31:25.774402       1 flags.go:64] FLAG: --requestheader-client-ca-file=""
2024-10-24T13:31:25.774442607Z I1024 13:31:25.774428       1 flags.go:64] FLAG: --requestheader-extra-headers-prefix="[x-remote-extra-]"
2024-10-24T13:31:25.774469227Z I1024 13:31:25.774457       1 flags.go:64] FLAG: --requestheader-group-headers="[x-remote-group]"
2024-10-24T13:31:25.774495757Z I1024 13:31:25.774483       1 flags.go:64] FLAG: --requestheader-username-headers="[x-remote-user]"
2024-10-24T13:31:25.774522087Z I1024 13:31:25.774510       1 flags.go:64] FLAG: --secure-port="10259"
2024-10-24T13:31:25.774550157Z I1024 13:31:25.774539       1 flags.go:64] FLAG: --show-hidden-metrics-for-version=""
2024-10-24T13:31:25.774578227Z I1024 13:31:25.774565       1 flags.go:64] FLAG: --tls-cert-file="/etc/kubernetes/static-pod-resources/secrets/serving-cert/tls.crt"
2024-10-24T13:31:25.774613817Z I1024 13:31:25.774594       1 flags.go:64] FLAG: --tls-cipher-suites="[TLS_ECDHE_ECDSA_WITH_AES_128_GCM_SHA256,TLS_ECDHE_RSA_WITH_AES_128_GCM_SHA256,TLS_ECDHE_ECDSA_WITH_AES_256_GCM_SHA384,TLS_ECDHE_RSA_WITH_AES_256_GCM_SHA384,TLS_ECDHE_ECDSA_WITH_CHACHA20_POLY1305_SHA256,TLS_ECDHE_RSA_WITH_CHACHA20_POLY1305_SHA256]"
2024-10-24T13:31:25.774644817Z I1024 13:31:25.774630       1 flags.go:64] FLAG: --tls-min-version="VersionTLS12"
2024-10-24T13:31:25.774674097Z I1024 13:31:25.774661       1 flags.go:64] FLAG: --tls-private-key-file="/etc/kubernetes/static-pod-resources/secrets/serving-cert/tls.key"
2024-10-24T13:31:25.774704117Z I1024 13:31:25.774690       1 flags.go:64] FLAG: --tls-sni-cert-key="[]"
2024-10-24T13:31:25.774732247Z I1024 13:31:25.774720       1 flags.go:64] FLAG: --unsupported-kube-api-over-localhost="false"
2024-10-24T13:31:25.774780807Z I1024 13:31:25.774765       1 flags.go:64] FLAG: --v="2"
2024-10-24T13:31:25.774816817Z I1024 13:31:25.774802       1 flags.go:64] FLAG: --version="false"
2024-10-24T13:31:25.774848217Z I1024 13:31:25.774834       1 flags.go:64] FLAG: --vmodule=""
2024-10-24T13:31:25.774876847Z I1024 13:31:25.774864       1 flags.go:64] FLAG: --write-config-to=""
2024-10-24T13:31:25.775143467Z W1024 13:31:25.775123       1 feature_gate.go:330] unrecognized feature gate: IngressControllerLBSubnetsAWS
2024-10-24T13:31:25.775185427Z W1024 13:31:25.775174       1 feature_gate.go:330] unrecognized feature gate: RouteAdvertisements
2024-10-24T13:31:25.775210417Z W1024 13:31:25.775201       1 feature_gate.go:330] unrecognized feature gate: ImageStreamImportMode
2024-10-24T13:31:25.775233927Z W1024 13:31:25.775224       1 feature_gate.go:330] unrecognized feature gate: VSphereMultiNetworks
2024-10-24T13:31:25.775258287Z W1024 13:31:25.775249       1 feature_gate.go:330] unrecognized feature gate: MachineAPIMigration
2024-10-24T13:31:25.775284617Z W1024 13:31:25.775274       1 feature_gate.go:330] unrecognized feature gate: AWSEFSDriverVolumeMetrics
2024-10-24T13:31:25.775311337Z W1024 13:31:25.775301       1 feature_gate.go:330] unrecognized feature gate: CSIDriverSharedResource
2024-10-24T13:31:25.775336707Z W1024 13:31:25.775326       1 feature_gate.go:330] unrecognized feature gate: PlatformOperators
2024-10-24T13:31:25.775364677Z W1024 13:31:25.775353       1 feature_gate.go:330] unrecognized feature gate: AdminNetworkPolicy
2024-10-24T13:31:25.775393757Z W1024 13:31:25.775382       1 feature_gate.go:330] unrecognized feature gate: ClusterAPIInstall
2024-10-24T13:31:25.775424087Z W1024 13:31:25.775411       1 feature_gate.go:330] unrecognized feature gate: ExternalOIDC
2024-10-24T13:31:25.775452797Z W1024 13:31:25.775441       1 feature_gate.go:330] unrecognized feature gate: MachineAPIOperatorDisableMachineHealthCheckController
2024-10-24T13:31:25.775482847Z W1024 13:31:25.775471       1 feature_gate.go:330] unrecognized feature gate: MixedCPUsAllocation
2024-10-24T13:31:25.775511007Z W1024 13:31:25.775499       1 feature_gate.go:330] unrecognized feature gate: BootcNodeManagement
2024-10-24T13:31:25.775550607Z W1024 13:31:25.775529       1 feature_gate.go:353] Setting GA feature gate CloudDualStackNodeIPs=true. It will be removed in a future release.
2024-10-24T13:31:25.775580057Z W1024 13:31:25.775569       1 feature_gate.go:330] unrecognized feature gate: BuildCSIVolumes
2024-10-24T13:31:25.775607977Z W1024 13:31:25.775596       1 feature_gate.go:330] unrecognized feature gate: InsightsConfig
2024-10-24T13:31:25.775635467Z W1024 13:31:25.775624       1 feature_gate.go:330] unrecognized feature gate: NewOLM
2024-10-24T13:31:25.775663637Z W1024 13:31:25.775652       1 feature_gate.go:330] unrecognized feature gate: GatewayAPI
2024-10-24T13:31:25.775691217Z W1024 13:31:25.775680       1 feature_gate.go:330] unrecognized feature gate: PersistentIPsForVirtualization
2024-10-24T13:31:25.775718037Z W1024 13:31:25.775707       1 feature_gate.go:330] unrecognized feature gate: MachineAPIProviderOpenStack
2024-10-24T13:31:25.775745507Z W1024 13:31:25.775735       1 feature_gate.go:330] unrecognized feature gate: ClusterAPIInstallIBMCloud
2024-10-24T13:31:25.775801657Z W1024 13:31:25.775788       1 feature_gate.go:330] unrecognized feature gate: OnClusterBuild
2024-10-24T13:31:25.775829857Z W1024 13:31:25.775819       1 feature_gate.go:330] unrecognized feature gate: ManagedBootImagesAWS
2024-10-24T13:31:25.775856007Z W1024 13:31:25.775845       1 feature_gate.go:330] unrecognized feature gate: NetworkLiveMigration
2024-10-24T13:31:25.775883217Z W1024 13:31:25.775872       1 feature_gate.go:330] unrecognized feature gate: AlibabaPlatform
2024-10-24T13:31:25.775908947Z W1024 13:31:25.775898       1 feature_gate.go:330] unrecognized feature gate: OVNObservability
2024-10-24T13:31:25.775936137Z W1024 13:31:25.775925       1 feature_gate.go:330] unrecognized feature gate: ChunkSizeMiB
2024-10-24T13:31:25.775973117Z W1024 13:31:25.775961       1 feature_gate.go:330] unrecognized feature gate: VSphereMultiVCenters
2024-10-24T13:31:25.775999347Z W1024 13:31:25.775988       1 feature_gate.go:330] unrecognized feature gate: BareMetalLoadBalancer
2024-10-24T13:31:25.776025697Z W1024 13:31:25.776015       1 feature_gate.go:330] unrecognized feature gate: InsightsRuntimeExtractor
2024-10-24T13:31:25.776052837Z W1024 13:31:25.776042       1 feature_gate.go:330] unrecognized feature gate: PinnedImages
2024-10-24T13:31:25.776078907Z W1024 13:31:25.776068       1 feature_gate.go:330] unrecognized feature gate: SigstoreImageVerification
2024-10-24T13:31:25.776104877Z W1024 13:31:25.776094       1 feature_gate.go:330] unrecognized feature gate: MetricsServer
2024-10-24T13:31:25.776134187Z W1024 13:31:25.776122       1 feature_gate.go:353] Setting GA feature gate DisableKubeletCloudCredentialProviders=true. It will be removed in a future release.
2024-10-24T13:31:25.776170407Z W1024 13:31:25.776158       1 feature_gate.go:330] unrecognized feature gate: MultiArchInstallGCP
2024-10-24T13:31:25.776214597Z W1024 13:31:25.776186       1 feature_gate.go:330] unrecognized feature gate: HardwareSpeed
2024-10-24T13:31:25.776240357Z W1024 13:31:25.776230       1 feature_gate.go:330] unrecognized feature gate: VolumeGroupSnapshot
2024-10-24T13:31:25.776264177Z W1024 13:31:25.776255       1 feature_gate.go:330] unrecognized feature gate: PrivateHostedZoneAWS
2024-10-24T13:31:25.776283507Z W1024 13:31:25.776275       1 feature_gate.go:330] unrecognized feature gate: UpgradeStatus
2024-10-24T13:31:25.776301647Z W1024 13:31:25.776294       1 feature_gate.go:330] unrecognized feature gate: IngressControllerDynamicConfigurationManager
2024-10-24T13:31:25.776320407Z W1024 13:31:25.776312       1 feature_gate.go:330] unrecognized feature gate: InsightsConfigAPI
2024-10-24T13:31:25.776338307Z W1024 13:31:25.776331       1 feature_gate.go:330] unrecognized feature gate: GCPClusterHostedDNS
2024-10-24T13:31:25.776355847Z W1024 13:31:25.776348       1 feature_gate.go:330] unrecognized feature gate: NodeDisruptionPolicy
2024-10-24T13:31:25.776373547Z W1024 13:31:25.776366       1 feature_gate.go:330] unrecognized feature gate: ManagedBootImages
2024-10-24T13:31:25.776392147Z W1024 13:31:25.776384       1 feature_gate.go:330] unrecognized feature gate: GCPLabelsTags
2024-10-24T13:31:25.776411597Z W1024 13:31:25.776404       1 feature_gate.go:330] unrecognized feature gate: AzureWorkloadIdentity
2024-10-24T13:31:25.776429757Z W1024 13:31:25.776422       1 feature_gate.go:330] unrecognized feature gate: VSphereStaticIPs
2024-10-24T13:31:25.776449537Z W1024 13:31:25.776442       1 feature_gate.go:330] unrecognized feature gate: AWSClusterHostedDNS
2024-10-24T13:31:25.776467337Z W1024 13:31:25.776460       1 feature_gate.go:330] unrecognized feature gate: Example
2024-10-24T13:31:25.776485667Z W1024 13:31:25.776478       1 feature_gate.go:330] unrecognized feature gate: NetworkSegmentation
2024-10-24T13:31:25.776508687Z W1024 13:31:25.776497       1 feature_gate.go:330] unrecognized feature gate: AdditionalRoutingCapabilities
2024-10-24T13:31:25.776535897Z W1024 13:31:25.776525       1 feature_gate.go:330] unrecognized feature gate: MultiArchInstallAWS
2024-10-24T13:31:25.776561897Z W1024 13:31:25.776551       1 feature_gate.go:330] unrecognized feature gate: DNSNameResolver
2024-10-24T13:31:25.776587297Z W1024 13:31:25.776578       1 feature_gate.go:330] unrecognized feature gate: SetEIPForNLBIngressController
2024-10-24T13:31:25.776611907Z W1024 13:31:25.776601       1 feature_gate.go:330] unrecognized feature gate: EtcdBackendQuota
2024-10-24T13:31:25.776637137Z W1024 13:31:25.776626       1 feature_gate.go:330] unrecognized feature gate: AutomatedEtcdBackup
2024-10-24T13:31:25.776669707Z W1024 13:31:25.776658       1 feature_gate.go:330] unrecognized feature gate: NetworkDiagnosticsConfig
2024-10-24T13:31:25.776696137Z W1024 13:31:25.776685       1 feature_gate.go:330] unrecognized feature gate: InsightsOnDemandDataGather
2024-10-24T13:31:25.776724857Z W1024 13:31:25.776713       1 feature_gate.go:351] Setting deprecated feature gate KMSv1=true. It will be removed in a future release.
2024-10-24T13:31:25.776778507Z W1024 13:31:25.776742       1 feature_gate.go:330] unrecognized feature gate: VSphereDriverConfiguration
2024-10-24T13:31:25.776818667Z W1024 13:31:25.776805       1 feature_gate.go:330] unrecognized feature gate: MachineConfigNodes
2024-10-24T13:31:25.776847197Z W1024 13:31:25.776836       1 feature_gate.go:330] unrecognized feature gate: ClusterMonitoringConfig
2024-10-24T13:31:25.776874147Z W1024 13:31:25.776863       1 feature_gate.go:330] unrecognized feature gate: MultiArchInstallAzure
2024-10-24T13:31:25.776901887Z W1024 13:31:25.776891       1 feature_gate.go:330] unrecognized feature gate: SignatureStores
2024-10-24T13:31:25.776930477Z W1024 13:31:25.776919       1 feature_gate.go:353] Setting GA feature gate ValidatingAdmissionPolicy=true. It will be removed in a future release.
2024-10-24T13:31:25.776957787Z W1024 13:31:25.776947       1 feature_gate.go:330] unrecognized feature gate: MetricsCollectionProfiles
2024-10-24T13:31:25.776985337Z W1024 13:31:25.776973       1 feature_gate.go:330] unrecognized feature gate: OpenShiftPodSecurityAdmission
2024-10-24T13:31:25.777012757Z W1024 13:31:25.777001       1 feature_gate.go:330] unrecognized feature gate: VSphereControlPlaneMachineSet
2024-10-24T13:31:25.778468727Z I1024 13:31:25.778442       1 dynamic_serving_content.go:116] "Loaded a new cert/key pair" name="serving-cert::/etc/kubernetes/static-pod-resources/secrets/serving-cert/tls.crt::/etc/kubernetes/static-pod-resources/secrets/serving-cert/tls.key"
2024-10-24T13:31:26.364143793Z I1024 13:31:26.364075       1 requestheader_controller.go:247] Loaded a new request header values for RequestHeaderAuthRequestController
2024-10-24T13:31:26.381610243Z I1024 13:31:26.381423       1 framework.go:392] "the scheduler starts to work with those plugins" Plugins={"PreEnqueue":{"Enabled":[{"Name":"SchedulingGates","Weight":0}],"Disabled":null},"QueueSort":{"Enabled":[{"Name":"PrioritySort","Weight":0}],"Disabled":null},"PreFilter":{"Enabled":[{"Name":"NodeAffinity","Weight":0},{"Name":"NodePorts","Weight":0},{"Name":"NodeResourcesFit","Weight":0},{"Name":"VolumeRestrictions","Weight":0},{"Name":"NodeVolumeLimits","Weight":0},{"Name":"VolumeBinding","Weight":0},{"Name":"VolumeZone","Weight":0},{"Name":"PodTopologySpread","Weight":0},{"Name":"InterPodAffinity","Weight":0}],"Disabled":null},"Filter":{"Enabled":[{"Name":"NodeUnschedulable","Weight":0},{"Name":"NodeName","Weight":0},{"Name":"TaintToleration","Weight":0},{"Name":"NodeAffinity","Weight":0},{"Name":"NodePorts","Weight":0},{"Name":"NodeResourcesFit","Weight":0},{"Name":"VolumeRestrictions","Weight":0},{"Name":"NodeVolumeLimits","Weight":0},{"Name":"VolumeBinding","Weight":0},{"Name":"VolumeZone","Weight":0},{"Name":"PodTopologySpread","Weight":0},{"Name":"InterPodAffinity","Weight":0}],"Disabled":null},"PostFilter":{"Enabled":[{"Name":"DefaultPreemption","Weight":0}],"Disabled":null},"PreScore":{"Enabled":[{"Name":"TaintToleration","Weight":0},{"Name":"NodeAffinity","Weight":0},{"Name":"NodeResourcesFit","Weight":0},{"Name":"VolumeBinding","Weight":0},{"Name":"PodTopologySpread","Weight":0},{"Name":"InterPodAffinity","Weight":0},{"Name":"NodeResourcesBalancedAllocation","Weight":0}],"Disabled":null},"Score":{"Enabled":[{"Name":"TaintToleration","Weight":3},{"Name":"NodeAffinity","Weight":2},{"Name":"NodeResourcesFit","Weight":1},{"Name":"VolumeBinding","Weight":1},{"Name":"PodTopologySpread","Weight":2},{"Name":"InterPodAffinity","Weight":2},{"Name":"NodeResourcesBalancedAllocation","Weight":1},{"Name":"ImageLocality","Weight":1}],"Disabled":null},"Reserve":{"Enabled":[{"Name":"VolumeBinding","Weight":0}],"Disabled":null},"Permit":{"Enabled":null,"Disabled":null},"PreBind":{"Enabled":[{"Name":"VolumeBinding","Weight":0}],"Disabled":null},"Bind":{"Enabled":[{"Name":"DefaultBinder","Weight":0}],"Disabled":null},"PostBind":{"Enabled":null,"Disabled":null},"MultiPoint":{"Enabled":null,"Disabled":null}}
2024-10-24T13:31:26.384149073Z I1024 13:31:26.384041       1 configfile.go:94] "Using component config" config=<
2024-10-24T13:31:26.384149073Z 	apiVersion: kubescheduler.config.k8s.io/v1
2024-10-24T13:31:26.384149073Z 	clientConnection:
2024-10-24T13:31:26.384149073Z 	  acceptContentTypes: ""
2024-10-24T13:31:26.384149073Z 	  burst: 100
2024-10-24T13:31:26.384149073Z 	  contentType: application/vnd.kubernetes.protobuf
2024-10-24T13:31:26.384149073Z 	  kubeconfig: /etc/kubernetes/static-pod-resources/configmaps/scheduler-kubeconfig/kubeconfig
2024-10-24T13:31:26.384149073Z 	  qps: 50
2024-10-24T13:31:26.384149073Z 	enableContentionProfiling: false
2024-10-24T13:31:26.384149073Z 	enableProfiling: false
2024-10-24T13:31:26.384149073Z 	kind: KubeSchedulerConfiguration
2024-10-24T13:31:26.384149073Z 	leaderElection:
2024-10-24T13:31:26.384149073Z 	  leaderElect: true
2024-10-24T13:31:26.384149073Z 	  leaseDuration: 2m17s
2024-10-24T13:31:26.384149073Z 	  renewDeadline: 1m47s
2024-10-24T13:31:26.384149073Z 	  resourceLock: leases
2024-10-24T13:31:26.384149073Z 	  resourceName: kube-scheduler
2024-10-24T13:31:26.384149073Z 	  resourceNamespace: openshift-kube-scheduler
2024-10-24T13:31:26.384149073Z 	  retryPeriod: 26s
2024-10-24T13:31:26.384149073Z 	parallelism: 16
2024-10-24T13:31:26.384149073Z 	percentageOfNodesToScore: 0
2024-10-24T13:31:26.384149073Z 	podInitialBackoffSeconds: 1
2024-10-24T13:31:26.384149073Z 	podMaxBackoffSeconds: 10
2024-10-24T13:31:26.384149073Z 	profiles:
2024-10-24T13:31:26.384149073Z 	- pluginConfig:
2024-10-24T13:31:26.384149073Z 	  - args:
2024-10-24T13:31:26.384149073Z 	      apiVersion: kubescheduler.config.k8s.io/v1
2024-10-24T13:31:26.384149073Z 	      kind: DefaultPreemptionArgs
2024-10-24T13:31:26.384149073Z 	      minCandidateNodesAbsolute: 100
2024-10-24T13:31:26.384149073Z 	      minCandidateNodesPercentage: 10
2024-10-24T13:31:26.384149073Z 	    name: DefaultPreemption
2024-10-24T13:31:26.384149073Z 	  - args:
2024-10-24T13:31:26.384149073Z 	      apiVersion: kubescheduler.config.k8s.io/v1
2024-10-24T13:31:26.384149073Z 	      hardPodAffinityWeight: 1
2024-10-24T13:31:26.384149073Z 	      ignorePreferredTermsOfExistingPods: false
2024-10-24T13:31:26.384149073Z 	      kind: InterPodAffinityArgs
2024-10-24T13:31:26.384149073Z 	    name: InterPodAffinity
2024-10-24T13:31:26.384149073Z 	  - args:
2024-10-24T13:31:26.384149073Z 	      apiVersion: kubescheduler.config.k8s.io/v1
2024-10-24T13:31:26.384149073Z 	      kind: NodeAffinityArgs
2024-10-24T13:31:26.384149073Z 	    name: NodeAffinity
2024-10-24T13:31:26.384149073Z 	  - args:
2024-10-24T13:31:26.384149073Z 	      apiVersion: kubescheduler.config.k8s.io/v1
2024-10-24T13:31:26.384149073Z 	      kind: NodeResourcesBalancedAllocationArgs
2024-10-24T13:31:26.384149073Z 	      resources:
2024-10-24T13:31:26.384149073Z 	      - name: cpu
2024-10-24T13:31:26.384149073Z 	        weight: 1
2024-10-24T13:31:26.384149073Z 	      - name: memory
2024-10-24T13:31:26.384149073Z 	        weight: 1
2024-10-24T13:31:26.384149073Z 	    name: NodeResourcesBalancedAllocation
2024-10-24T13:31:26.384149073Z 	  - args:
2024-10-24T13:31:26.384149073Z 	      apiVersion: kubescheduler.config.k8s.io/v1
2024-10-24T13:31:26.384149073Z 	      kind: NodeResourcesFitArgs
2024-10-24T13:31:26.384149073Z 	      scoringStrategy:
2024-10-24T13:31:26.384149073Z 	        resources:
2024-10-24T13:31:26.384149073Z 	        - name: cpu
2024-10-24T13:31:26.384149073Z 	          weight: 1
2024-10-24T13:31:26.384149073Z 	        - name: memory
2024-10-24T13:31:26.384149073Z 	          weight: 1
2024-10-24T13:31:26.384149073Z 	        type: LeastAllocated
2024-10-24T13:31:26.384149073Z 	    name: NodeResourcesFit
2024-10-24T13:31:26.384149073Z 	  - args:
2024-10-24T13:31:26.384149073Z 	      apiVersion: kubescheduler.config.k8s.io/v1
2024-10-24T13:31:26.384149073Z 	      defaultingType: System
2024-10-24T13:31:26.384149073Z 	      kind: PodTopologySpreadArgs
2024-10-24T13:31:26.384149073Z 	    name: PodTopologySpread
2024-10-24T13:31:26.384149073Z 	  - args:
2024-10-24T13:31:26.384149073Z 	      apiVersion: kubescheduler.config.k8s.io/v1
2024-10-24T13:31:26.384149073Z 	      bindTimeoutSeconds: 600
2024-10-24T13:31:26.384149073Z 	      kind: VolumeBindingArgs
2024-10-24T13:31:26.384149073Z 	    name: VolumeBinding
2024-10-24T13:31:26.384149073Z 	  plugins:
2024-10-24T13:31:26.384149073Z 	    bind: {}
2024-10-24T13:31:26.384149073Z 	    filter: {}
2024-10-24T13:31:26.384149073Z 	    multiPoint:
2024-10-24T13:31:26.384149073Z 	      enabled:
2024-10-24T13:31:26.384149073Z 	      - name: SchedulingGates
2024-10-24T13:31:26.384149073Z 	        weight: 0
2024-10-24T13:31:26.384149073Z 	      - name: PrioritySort
2024-10-24T13:31:26.384149073Z 	        weight: 0
2024-10-24T13:31:26.384149073Z 	      - name: NodeUnschedulable
2024-10-24T13:31:26.384149073Z 	        weight: 0
2024-10-24T13:31:26.384149073Z 	      - name: NodeName
2024-10-24T13:31:26.384149073Z 	        weight: 0
2024-10-24T13:31:26.384149073Z 	      - name: TaintToleration
2024-10-24T13:31:26.384149073Z 	        weight: 3
2024-10-24T13:31:26.384149073Z 	      - name: NodeAffinity
2024-10-24T13:31:26.384149073Z 	        weight: 2
2024-10-24T13:31:26.384149073Z 	      - name: NodePorts
2024-10-24T13:31:26.384149073Z 	        weight: 0
2024-10-24T13:31:26.384149073Z 	      - name: NodeResourcesFit
2024-10-24T13:31:26.384149073Z 	        weight: 1
2024-10-24T13:31:26.384149073Z 	      - name: VolumeRestrictions
2024-10-24T13:31:26.384149073Z 	        weight: 0
2024-10-24T13:31:26.384149073Z 	      - name: NodeVolumeLimits
2024-10-24T13:31:26.384149073Z 	        weight: 0
2024-10-24T13:31:26.384149073Z 	      - name: VolumeBinding
2024-10-24T13:31:26.384149073Z 	        weight: 0
2024-10-24T13:31:26.384149073Z 	      - name: VolumeZone
2024-10-24T13:31:26.384149073Z 	        weight: 0
2024-10-24T13:31:26.384149073Z 	      - name: PodTopologySpread
2024-10-24T13:31:26.384149073Z 	        weight: 2
2024-10-24T13:31:26.384149073Z 	      - name: InterPodAffinity
2024-10-24T13:31:26.384149073Z 	        weight: 2
2024-10-24T13:31:26.384149073Z 	      - name: DefaultPreemption
2024-10-24T13:31:26.384149073Z 	        weight: 0
2024-10-24T13:31:26.384149073Z 	      - name: NodeResourcesBalancedAllocation
2024-10-24T13:31:26.384149073Z 	        weight: 1
2024-10-24T13:31:26.384149073Z 	      - name: ImageLocality
2024-10-24T13:31:26.384149073Z 	        weight: 1
2024-10-24T13:31:26.384149073Z 	      - name: DefaultBinder
2024-10-24T13:31:26.384149073Z 	        weight: 0
2024-10-24T13:31:26.384149073Z 	    permit: {}
2024-10-24T13:31:26.384149073Z 	    postBind: {}
2024-10-24T13:31:26.384149073Z 	    postFilter: {}
2024-10-24T13:31:26.384149073Z 	    preBind: {}
2024-10-24T13:31:26.384149073Z 	    preEnqueue: {}
2024-10-24T13:31:26.384149073Z 	    preFilter: {}
2024-10-24T13:31:26.384149073Z 	    preScore: {}
2024-10-24T13:31:26.384149073Z 	    queueSort: {}
2024-10-24T13:31:26.384149073Z 	    reserve: {}
2024-10-24T13:31:26.384149073Z 	    score: {}
2024-10-24T13:31:26.384149073Z 	  schedulerName: default-scheduler
2024-10-24T13:31:26.384149073Z  >
2024-10-24T13:31:26.385418363Z I1024 13:31:26.385345       1 server.go:172] "Starting Kubernetes Scheduler" version="v1.31.1-dirty"
2024-10-24T13:31:26.385418363Z I1024 13:31:26.385367       1 server.go:174] "Golang settings" GOGC="" GOMAXPROCS="" GOTRACEBACK=""
2024-10-24T13:31:26.394688543Z I1024 13:31:26.394624       1 requestheader_controller.go:172] Starting RequestHeaderAuthRequestController
2024-10-24T13:31:26.394800243Z I1024 13:31:26.394782       1 shared_informer.go:313] Waiting for caches to sync for RequestHeaderAuthRequestController
2024-10-24T13:31:26.394889683Z I1024 13:31:26.394669       1 configmap_cafile_content.go:205] "Starting controller" name="client-ca::kube-system::extension-apiserver-authentication::requestheader-client-ca-file"
2024-10-24T13:31:26.395037583Z I1024 13:31:26.394970       1 dynamic_serving_content.go:135] "Starting controller" name="serving-cert::/etc/kubernetes/static-pod-resources/secrets/serving-cert/tls.crt::/etc/kubernetes/static-pod-resources/secrets/serving-cert/tls.key"
2024-10-24T13:31:26.395037583Z I1024 13:31:26.394669       1 configmap_cafile_content.go:205] "Starting controller" name="client-ca::kube-system::extension-apiserver-authentication::client-ca-file"
2024-10-24T13:31:26.395081803Z I1024 13:31:26.395032       1 tlsconfig.go:203] "Loaded serving cert" certName="serving-cert::/etc/kubernetes/static-pod-resources/secrets/serving-cert/tls.crt::/etc/kubernetes/static-pod-resources/secrets/serving-cert/tls.key" certDetail="\"scheduler.openshift-kube-scheduler.svc\" [serving] validServingFor=[scheduler.openshift-kube-scheduler.svc,scheduler.openshift-kube-scheduler.svc.cluster.local] issuer=\"openshift-service-serving-signer@1729775010\" (2024-10-24 13:03:41 +0000 UTC to 2026-10-24 13:03:42 +0000 UTC (now=2024-10-24 13:31:26.394985413 +0000 UTC))"
2024-10-24T13:31:26.395118763Z I1024 13:31:26.394970       1 shared_informer.go:313] Waiting for caches to sync for client-ca::kube-system::extension-apiserver-authentication::requestheader-client-ca-file
2024-10-24T13:31:26.395178333Z I1024 13:31:26.395038       1 shared_informer.go:313] Waiting for caches to sync for client-ca::kube-system::extension-apiserver-authentication::client-ca-file
2024-10-24T13:31:26.395289953Z I1024 13:31:26.395229       1 named_certificates.go:53] "Loaded SNI cert" index=0 certName="self-signed loopback" certDetail="\"apiserver-loopback-client@1729776686\" [serving] validServingFor=[apiserver-loopback-client] issuer=\"apiserver-loopback-client-ca@1729776685\" (2024-10-24 12:31:25 +0000 UTC to 2025-10-24 12:31:25 +0000 UTC (now=2024-10-24 13:31:26.395212363 +0000 UTC))"
2024-10-24T13:31:26.395415493Z I1024 13:31:26.395366       1 secure_serving.go:213] Serving securely on [::]:10259
2024-10-24T13:31:26.395458213Z I1024 13:31:26.395432       1 tlsconfig.go:243] "Starting DynamicServingCertificateController"
2024-10-24T13:31:26.399133943Z I1024 13:31:26.399104       1 reflector.go:368] Caches populated for *v1.StorageClass from k8s.io/client-go/informers/factory.go:160
2024-10-24T13:31:26.399282283Z I1024 13:31:26.399259       1 reflector.go:368] Caches populated for *v1.ConfigMap from runtime/asm_amd64.s:1695
2024-10-24T13:31:26.399493623Z I1024 13:31:26.399461       1 reflector.go:368] Caches populated for *v1.CSINode from k8s.io/client-go/informers/factory.go:160
2024-10-24T13:31:26.399615503Z I1024 13:31:26.399394       1 reflector.go:368] Caches populated for *v1.PersistentVolumeClaim from k8s.io/client-go/informers/factory.go:160
2024-10-24T13:31:26.399825403Z I1024 13:31:26.399804       1 reflector.go:368] Caches populated for *v1.CSIStorageCapacity from k8s.io/client-go/informers/factory.go:160
2024-10-24T13:31:26.400649423Z I1024 13:31:26.400625       1 reflector.go:368] Caches populated for *v1.ConfigMap from runtime/asm_amd64.s:1695
2024-10-24T13:31:26.400718493Z I1024 13:31:26.400691       1 reflector.go:368] Caches populated for *v1.ConfigMap from runtime/asm_amd64.s:1695
2024-10-24T13:31:26.401941263Z I1024 13:31:26.401883       1 reflector.go:368] Caches populated for *v1.CSIDriver from k8s.io/client-go/informers/factory.go:160
2024-10-24T13:31:26.402077433Z I1024 13:31:26.402038       1 reflector.go:368] Caches populated for *v1.PersistentVolume from k8s.io/client-go/informers/factory.go:160
2024-10-24T13:31:26.402606303Z I1024 13:31:26.402524       1 reflector.go:368] Caches populated for *v1.StatefulSet from k8s.io/client-go/informers/factory.go:160
2024-10-24T13:31:26.403471063Z I1024 13:31:26.403432       1 reflector.go:368] Caches populated for *v1.PodDisruptionBudget from k8s.io/client-go/informers/factory.go:160
2024-10-24T13:31:26.404103203Z I1024 13:31:26.404069       1 reflector.go:368] Caches populated for *v1.Namespace from k8s.io/client-go/informers/factory.go:160
2024-10-24T13:31:26.404186253Z I1024 13:31:26.404156       1 reflector.go:368] Caches populated for *v1.ReplicationController from k8s.io/client-go/informers/factory.go:160
2024-10-24T13:31:26.405944883Z I1024 13:31:26.405898       1 reflector.go:368] Caches populated for *v1.Node from k8s.io/client-go/informers/factory.go:160
2024-10-24T13:31:26.406591703Z I1024 13:31:26.406503       1 node_tree.go:65] "Added node in listed group to NodeTree" node="ci-op-2fcpj5j6-f6035-2lklf-master-0" zone="us-central1:\x00:us-central1-a"
2024-10-24T13:31:26.406945213Z I1024 13:31:26.406845       1 node_tree.go:65] "Added node in listed group to NodeTree" node="ci-op-2fcpj5j6-f6035-2lklf-master-1" zone="us-central1:\x00:us-central1-b"
2024-10-24T13:31:26.407470133Z I1024 13:31:26.407325       1 node_tree.go:65] "Added node in listed group to NodeTree" node="ci-op-2fcpj5j6-f6035-2lklf-master-2" zone="us-central1:\x00:us-central1-c"
2024-10-24T13:31:26.408027663Z I1024 13:31:26.407369       1 reflector.go:368] Caches populated for *v1.Service from k8s.io/client-go/informers/factory.go:160
2024-10-24T13:31:26.408413453Z I1024 13:31:26.408359       1 node_tree.go:65] "Added node in listed group to NodeTree" node="ci-op-2fcpj5j6-f6035-2lklf-worker-a-8hj4x" zone="us-central1:\x00:us-central1-a"
2024-10-24T13:31:26.408700443Z I1024 13:31:26.408680       1 node_tree.go:65] "Added node in listed group to NodeTree" node="ci-op-2fcpj5j6-f6035-2lklf-worker-b-hj8l2" zone="us-central1:\x00:us-central1-b"
2024-10-24T13:31:26.408893493Z I1024 13:31:26.408872       1 node_tree.go:65] "Added node in listed group to NodeTree" node="ci-op-2fcpj5j6-f6035-2lklf-worker-c-z8hfz" zone="us-central1:\x00:us-central1-c"
2024-10-24T13:31:26.430829043Z I1024 13:31:26.430736       1 reflector.go:368] Caches populated for *v1.ReplicaSet from k8s.io/client-go/informers/factory.go:160
2024-10-24T13:31:26.437962133Z I1024 13:31:26.437904       1 reflector.go:368] Caches populated for *v1.Pod from k8s.io/client-go/informers/factory.go:160
2024-10-24T13:31:26.495550862Z I1024 13:31:26.495501       1 shared_informer.go:320] Caches are synced for RequestHeaderAuthRequestController
2024-10-24T13:31:26.495681202Z I1024 13:31:26.495631       1 leaderelection.go:254] attempting to acquire leader lease openshift-kube-scheduler/kube-scheduler...
2024-10-24T13:31:26.495856243Z I1024 13:31:26.495637       1 shared_informer.go:320] Caches are synced for client-ca::kube-system::extension-apiserver-authentication::client-ca-file
2024-10-24T13:31:26.496020403Z I1024 13:31:26.495647       1 shared_informer.go:320] Caches are synced for client-ca::kube-system::extension-apiserver-authentication::requestheader-client-ca-file
2024-10-24T13:31:26.496254622Z I1024 13:31:26.496214       1 tlsconfig.go:181] "Loaded client CA" index=0 certName="client-ca::kube-system::extension-apiserver-authentication::client-ca-file,client-ca::kube-system::extension-apiserver-authentication::requestheader-client-ca-file" certDetail="\"aggregator-signer\" [] issuer=\"<self>\" (2024-10-24 12:49:32 +0000 UTC to 2024-10-25 12:49:32 +0000 UTC (now=2024-10-24 13:31:26.496196862 +0000 UTC))"
2024-10-24T13:31:26.496388052Z I1024 13:31:26.496358       1 tlsconfig.go:203] "Loaded serving cert" certName="serving-cert::/etc/kubernetes/static-pod-resources/secrets/serving-cert/tls.crt::/etc/kubernetes/static-pod-resources/secrets/serving-cert/tls.key" certDetail="\"scheduler.openshift-kube-scheduler.svc\" [serving] validServingFor=[scheduler.openshift-kube-scheduler.svc,scheduler.openshift-kube-scheduler.svc.cluster.local] issuer=\"openshift-service-serving-signer@1729775010\" (2024-10-24 13:03:41 +0000 UTC to 2026-10-24 13:03:42 +0000 UTC (now=2024-10-24 13:31:26.496349112 +0000 UTC))"
2024-10-24T13:31:26.496470503Z I1024 13:31:26.496453       1 named_certificates.go:53] "Loaded SNI cert" index=0 certName="self-signed loopback" certDetail="\"apiserver-loopback-client@1729776686\" [serving] validServingFor=[apiserver-loopback-client] issuer=\"apiserver-loopback-client-ca@1729776685\" (2024-10-24 12:31:25 +0000 UTC to 2025-10-24 12:31:25 +0000 UTC (now=2024-10-24 13:31:26.496445863 +0000 UTC))"
2024-10-24T13:31:26.496569212Z I1024 13:31:26.496552       1 tlsconfig.go:181] "Loaded client CA" index=0 certName="client-ca::kube-system::extension-apiserver-authentication::client-ca-file,client-ca::kube-system::extension-apiserver-authentication::requestheader-client-ca-file" certDetail="\"admin-kubeconfig-signer\" [] issuer=\"<self>\" (2024-10-24 12:49:31 +0000 UTC to 2034-10-22 12:49:31 +0000 UTC (now=2024-10-24 13:31:26.496546872 +0000 UTC))"
2024-10-24T13:31:26.496577203Z I1024 13:31:26.496569       1 tlsconfig.go:181] "Loaded client CA" index=1 certName="client-ca::kube-system::extension-apiserver-authentication::client-ca-file,client-ca::kube-system::extension-apiserver-authentication::requestheader-client-ca-file" certDetail="\"kubelet-signer\" [] issuer=\"<self>\" (2024-10-24 12:49:34 +0000 UTC to 2024-10-25 12:49:34 +0000 UTC (now=2024-10-24 13:31:26.496565503 +0000 UTC))"
2024-10-24T13:31:26.496594822Z I1024 13:31:26.496580       1 tlsconfig.go:181] "Loaded client CA" index=2 certName="client-ca::kube-system::extension-apiserver-authentication::client-ca-file,client-ca::kube-system::extension-apiserver-authentication::requestheader-client-ca-file" certDetail="\"kube-control-plane-signer\" [] issuer=\"<self>\" (2024-10-24 12:49:34 +0000 UTC to 2025-10-24 12:49:34 +0000 UTC (now=2024-10-24 13:31:26.496576523 +0000 UTC))"
2024-10-24T13:31:26.496610292Z I1024 13:31:26.496594       1 tlsconfig.go:181] "Loaded client CA" index=3 certName="client-ca::kube-system::extension-apiserver-authentication::client-ca-file,client-ca::kube-system::extension-apiserver-authentication::requestheader-client-ca-file" certDetail="\"kube-apiserver-to-kubelet-signer\" [] issuer=\"<self>\" (2024-10-24 12:49:34 +0000 UTC to 2025-10-24 12:49:34 +0000 UTC (now=2024-10-24 13:31:26.496591412 +0000 UTC))"
2024-10-24T13:31:26.496610292Z I1024 13:31:26.496604       1 tlsconfig.go:181] "Loaded client CA" index=4 certName="client-ca::kube-system::extension-apiserver-authentication::client-ca-file,client-ca::kube-system::extension-apiserver-authentication::requestheader-client-ca-file" certDetail="\"kubelet-bootstrap-kubeconfig-signer\" [] issuer=\"<self>\" (2024-10-24 12:49:32 +0000 UTC to 2034-10-22 12:49:32 +0000 UTC (now=2024-10-24 13:31:26.496601532 +0000 UTC))"
2024-10-24T13:31:26.496628802Z I1024 13:31:26.496614       1 tlsconfig.go:181] "Loaded client CA" index=5 certName="client-ca::kube-system::extension-apiserver-authentication::client-ca-file,client-ca::kube-system::extension-apiserver-authentication::requestheader-client-ca-file" certDetail="\"kube-csr-signer_@1729775012\" [] issuer=\"kubelet-signer\" (2024-10-24 13:03:31 +0000 UTC to 2024-10-25 12:49:34 +0000 UTC (now=2024-10-24 13:31:26.496611722 +0000 UTC))"
2024-10-24T13:31:26.496650542Z I1024 13:31:26.496628       1 tlsconfig.go:181] "Loaded client CA" index=6 certName="client-ca::kube-system::extension-apiserver-authentication::client-ca-file,client-ca::kube-system::extension-apiserver-authentication::requestheader-client-ca-file" certDetail="\"openshift-kube-apiserver-operator_node-system-admin-signer@1729775011\" [] issuer=\"<self>\" (2024-10-24 13:03:30 +0000 UTC to 2025-10-24 13:03:31 +0000 UTC (now=2024-10-24 13:31:26.496623762 +0000 UTC))"
2024-10-24T13:31:26.496656933Z I1024 13:31:26.496649       1 tlsconfig.go:181] "Loaded client CA" index=7 certName="client-ca::kube-system::extension-apiserver-authentication::client-ca-file,client-ca::kube-system::extension-apiserver-authentication::requestheader-client-ca-file" certDetail="\"aggregator-signer\" [] issuer=\"<self>\" (2024-10-24 12:49:32 +0000 UTC to 2024-10-25 12:49:32 +0000 UTC (now=2024-10-24 13:31:26.496646173 +0000 UTC))"
2024-10-24T13:31:26.496830382Z I1024 13:31:26.496810       1 tlsconfig.go:203] "Loaded serving cert" certName="serving-cert::/etc/kubernetes/static-pod-resources/secrets/serving-cert/tls.crt::/etc/kubernetes/static-pod-resources/secrets/serving-cert/tls.key" certDetail="\"scheduler.openshift-kube-scheduler.svc\" [serving] validServingFor=[scheduler.openshift-kube-scheduler.svc,scheduler.openshift-kube-scheduler.svc.cluster.local] issuer=\"openshift-service-serving-signer@1729775010\" (2024-10-24 13:03:41 +0000 UTC to 2026-10-24 13:03:42 +0000 UTC (now=2024-10-24 13:31:26.496800982 +0000 UTC))"
2024-10-24T13:31:26.496915472Z I1024 13:31:26.496899       1 named_certificates.go:53] "Loaded SNI cert" index=0 certName="self-signed loopback" certDetail="\"apiserver-loopback-client@1729776686\" [serving] validServingFor=[apiserver-loopback-client] issuer=\"apiserver-loopback-client-ca@1729776685\" (2024-10-24 12:31:25 +0000 UTC to 2025-10-24 12:31:25 +0000 UTC (now=2024-10-24 13:31:26.496893902 +0000 UTC))"
2024-10-24T13:32:37.134780071Z E1024 13:32:37.134682       1 leaderelection.go:436] error retrieving resource lock openshift-kube-scheduler/kube-scheduler: Get "https://api-int.ci-op-2fcpj5j6-f6035.XXXXXXXXXXXXXXXXXXXXXX:6443/apis/coordination.k8s.io/v1/namespaces/openshift-kube-scheduler/leases/kube-scheduler?timeout=53.5s": dial tcp 10.0.0.2:6443: connect: connection refused
2024-10-24T13:32:44.754045172Z I1024 13:32:44.753979       1 reflector.go:368] Caches populated for *v1.ReplicaSet from k8s.io/client-go/informers/factory.go:160
2024-10-24T13:32:44.930980210Z I1024 13:32:44.930913       1 reflector.go:368] Caches populated for *v1.Pod from k8s.io/client-go/informers/factory.go:160
2024-10-24T13:32:45.145733887Z I1024 13:32:45.145661       1 reflector.go:368] Caches populated for *v1.Service from k8s.io/client-go/informers/factory.go:160
2024-10-24T13:32:45.303970265Z I1024 13:32:45.303904       1 reflector.go:368] Caches populated for *v1.CSIDriver from k8s.io/client-go/informers/factory.go:160
2024-10-24T13:32:45.413349123Z I1024 13:32:45.413273       1 reflector.go:368] Caches populated for *v1.StorageClass from k8s.io/client-go/informers/factory.go:160
2024-10-24T13:32:45.687449089Z I1024 13:32:45.687372       1 reflector.go:368] Caches populated for *v1.PodDisruptionBudget from k8s.io/client-go/informers/factory.go:160
2024-10-24T13:32:54.699615102Z I1024 13:32:54.699533       1 reflector.go:368] Caches populated for *v1.PersistentVolume from k8s.io/client-go/informers/factory.go:160
2024-10-24T13:32:55.040210157Z I1024 13:32:55.040141       1 reflector.go:368] Caches populated for *v1.Namespace from k8s.io/client-go/informers/factory.go:160
2024-10-24T13:32:56.057479052Z I1024 13:32:56.057432       1 reflector.go:368] Caches populated for *v1.ReplicationController from k8s.io/client-go/informers/factory.go:160
2024-10-24T13:33:01.210048489Z I1024 13:33:01.209981       1 reflector.go:368] Caches populated for *v1.CSIStorageCapacity from k8s.io/client-go/informers/factory.go:160
2024-10-24T13:33:03.343565869Z I1024 13:33:03.343497       1 reflector.go:368] Caches populated for *v1.ConfigMap from runtime/asm_amd64.s:1695
2024-10-24T13:33:04.177722897Z I1024 13:33:04.177647       1 reflector.go:368] Caches populated for *v1.Node from k8s.io/client-go/informers/factory.go:160
2024-10-24T13:33:05.928502502Z I1024 13:33:05.928439       1 reflector.go:368] Caches populated for *v1.StatefulSet from k8s.io/client-go/informers/factory.go:160
2024-10-24T13:33:06.060846230Z I1024 13:33:06.060792       1 reflector.go:368] Caches populated for *v1.ConfigMap from runtime/asm_amd64.s:1695
2024-10-24T13:33:08.528091265Z I1024 13:33:08.528005       1 reflector.go:368] Caches populated for *v1.CSINode from k8s.io/client-go/informers/factory.go:160
2024-10-24T13:33:09.030875478Z I1024 13:33:09.030812       1 reflector.go:368] Caches populated for *v1.PersistentVolumeClaim from k8s.io/client-go/informers/factory.go:160
2024-10-24T13:33:13.710039841Z I1024 13:33:13.709976       1 reflector.go:368] Caches populated for *v1.ConfigMap from runtime/asm_amd64.s:1695
2024-10-24T13:34:58.874198615Z I1024 13:34:58.874124       1 leaderelection.go:268] successfully acquired lease openshift-kube-scheduler/kube-scheduler
2024-10-24T13:34:58.875268095Z I1024 13:34:58.875217       1 schedule_one.go:1055] "Unable to schedule pod; no fit; waiting" pod="openshift-apiserver/apiserver-79fb6d9f75-wm8d6" err="0/6 nodes are available: 3 node(s) didn't match Pod's node affinity/selector, 3 node(s) didn't match pod anti-affinity rules. preemption: 0/6 nodes are available: 3 Preemption is not helpful for scheduling, 3 node(s) didn't match pod anti-affinity rules."
2024-10-24T13:35:00.986603715Z I1024 13:35:00.986520       1 schedule_one.go:1055] "Unable to schedule pod; no fit; waiting" pod="openshift-apiserver/apiserver-79fb6d9f75-wm8d6" err="0/6 nodes are available: 3 node(s) didn't match Pod's node affinity/selector, 3 node(s) didn't match pod anti-affinity rules. preemption: 0/6 nodes are available: 3 Preemption is not helpful for scheduling, 3 node(s) didn't match pod anti-affinity rules."
2024-10-24T13:35:05.167427516Z I1024 13:35:05.167341       1 schedule_one.go:1055] "Unable to schedule pod; no fit; waiting" pod="openshift-apiserver/apiserver-79fb6d9f75-wm8d6" err="0/6 nodes are available: 3 node(s) didn't match Pod's node affinity/selector, 3 node(s) didn't match pod anti-affinity rules. preemption: 0/6 nodes are available: 3 Preemption is not helpful for scheduling, 3 node(s) didn't match pod anti-affinity rules."
2024-10-24T13:35:12.869646946Z I1024 13:35:12.869571       1 schedule_one.go:1055] "Unable to schedule pod; no fit; waiting" pod="openshift-apiserver/apiserver-79fb6d9f75-wm8d6" err="0/6 nodes are available: 3 node(s) didn't match Pod's node affinity/selector, 3 node(s) didn't match pod anti-affinity rules. preemption: 0/6 nodes are available: 3 Preemption is not helpful for scheduling, 3 node(s) didn't match pod anti-affinity rules."
2024-10-24T13:35:33.081371269Z I1024 13:35:33.081314       1 schedule_one.go:314] "Successfully bound pod to node" pod="openshift-apiserver/apiserver-79fb6d9f75-wm8d6" node="ci-op-2fcpj5j6-f6035-2lklf-master-0" evaluatedNodes=6 feasibleNodes=1
2024-10-24T13:35:38.923072646Z I1024 13:35:38.923000       1 schedule_one.go:1055] "Unable to schedule pod; no fit; waiting" pod="openshift-apiserver/apiserver-79fb6d9f75-d2mgw" err="0/6 nodes are available: 3 node(s) didn't match Pod's node affinity/selector, 3 node(s) didn't match pod anti-affinity rules. preemption: 0/6 nodes are available: 3 Preemption is not helpful for scheduling, 3 node(s) didn't match pod anti-affinity rules."
2024-10-24T13:35:57.547191059Z I1024 13:35:57.547140       1 schedule_one.go:1055] "Unable to schedule pod; no fit; waiting" pod="openshift-apiserver/apiserver-79fb6d9f75-d2mgw" err="0/6 nodes are available: 3 node(s) didn't match Pod's node affinity/selector, 3 node(s) didn't match pod anti-affinity rules. preemption: 0/6 nodes are available: 3 Preemption is not helpful for scheduling, 3 node(s) didn't match pod anti-affinity rules."
2024-10-24T13:36:12.615426284Z I1024 13:36:12.615361       1 schedule_one.go:314] "Successfully bound pod to node" pod="openshift-marketplace/certified-operators-hn5hn" node="ci-op-2fcpj5j6-f6035-2lklf-master-2" evaluatedNodes=6 feasibleNodes=3
2024-10-24T13:36:24.634207494Z I1024 13:36:24.634141       1 schedule_one.go:1055] "Unable to schedule pod; no fit; waiting" pod="openshift-apiserver/apiserver-79fb6d9f75-d2mgw" err="0/6 nodes are available: 3 node(s) didn't match Pod's node affinity/selector, 3 node(s) didn't match pod anti-affinity rules. preemption: 0/6 nodes are available: 3 Preemption is not helpful for scheduling, 3 node(s) didn't match pod anti-affinity rules."
2024-10-24T13:36:28.924170234Z I1024 13:36:28.924107       1 schedule_one.go:1055] "Unable to schedule pod; no fit; waiting" pod="openshift-apiserver/apiserver-79fb6d9f75-d2mgw" err="0/6 nodes are available: 3 node(s) didn't match Pod's node affinity/selector, 3 node(s) didn't match pod anti-affinity rules. preemption: 0/6 nodes are available: 3 Preemption is not helpful for scheduling, 3 node(s) didn't match pod anti-affinity rules."
2024-10-24T13:36:36.927934971Z I1024 13:36:36.927862       1 schedule_one.go:1055] "Unable to schedule pod; no fit; waiting" pod="openshift-apiserver/apiserver-79fb6d9f75-d2mgw" err="0/6 nodes are available: 3 node(s) didn't match Pod's node affinity/selector, 3 node(s) didn't match pod anti-affinity rules. preemption: 0/6 nodes are available: 3 Preemption is not helpful for scheduling, 3 node(s) didn't match pod anti-affinity rules."
2024-10-24T13:37:16.458254767Z I1024 13:37:16.458195       1 schedule_one.go:314] "Successfully bound pod to node" pod="openshift-marketplace/community-operators-5bkrv" node="ci-op-2fcpj5j6-f6035-2lklf-master-2" evaluatedNodes=6 feasibleNodes=3
2024-10-24T13:37:29.282004802Z I1024 13:37:29.281947       1 schedule_one.go:314] "Successfully bound pod to node" pod="openshift-apiserver/apiserver-79fb6d9f75-d2mgw" node="ci-op-2fcpj5j6-f6035-2lklf-master-2" evaluatedNodes=6 feasibleNodes=1
2024-10-24T13:41:03.028623906Z I1024 13:41:03.028544       1 schedule_one.go:314] "Successfully bound pod to node" pod="openshift-marketplace/redhat-marketplace-7d926" node="ci-op-2fcpj5j6-f6035-2lklf-master-2" evaluatedNodes=6 feasibleNodes=3
2024-10-24T13:45:00.234729952Z I1024 13:45:00.234615       1 schedule_one.go:314] "Successfully bound pod to node" pod="openshift-operator-lifecycle-manager/collect-profiles-28829625-629m7" node="ci-op-2fcpj5j6-f6035-2lklf-worker-a-8hj4x" evaluatedNodes=6 feasibleNodes=3
2024-10-24T13:46:21.796035610Z I1024 13:46:21.795228       1 tlsconfig.go:181] "Loaded client CA" index=0 certName="client-ca::kube-system::extension-apiserver-authentication::client-ca-file,client-ca::kube-system::extension-apiserver-authentication::requestheader-client-ca-file" certDetail="\"admin-kubeconfig-signer\" [] issuer=\"<self>\" (2024-10-24 12:49:31 +0000 UTC to 2034-10-22 12:49:31 +0000 UTC (now=2024-10-24 13:46:21.795159009 +0000 UTC))"
2024-10-24T13:46:21.796035610Z I1024 13:46:21.795285       1 tlsconfig.go:181] "Loaded client CA" index=1 certName="client-ca::kube-system::extension-apiserver-authentication::client-ca-file,client-ca::kube-system::extension-apiserver-authentication::requestheader-client-ca-file" certDetail="\"kubelet-signer\" [] issuer=\"<self>\" (2024-10-24 12:49:34 +0000 UTC to 2024-10-25 12:49:34 +0000 UTC (now=2024-10-24 13:46:21.79527841 +0000 UTC))"
2024-10-24T13:46:21.796035610Z I1024 13:46:21.795303       1 tlsconfig.go:181] "Loaded client CA" index=2 certName="client-ca::kube-system::extension-apiserver-authentication::client-ca-file,client-ca::kube-system::extension-apiserver-authentication::requestheader-client-ca-file" certDetail="\"kube-control-plane-signer\" [] issuer=\"<self>\" (2024-10-24 12:49:34 +0000 UTC to 2025-10-24 12:49:34 +0000 UTC (now=2024-10-24 13:46:21.79529714 +0000 UTC))"
2024-10-24T13:46:21.796035610Z I1024 13:46:21.795323       1 tlsconfig.go:181] "Loaded client CA" index=3 certName="client-ca::kube-system::extension-apiserver-authentication::client-ca-file,client-ca::kube-system::extension-apiserver-authentication::requestheader-client-ca-file" certDetail="\"kube-apiserver-to-kubelet-signer\" [] issuer=\"<self>\" (2024-10-24 12:49:34 +0000 UTC to 2025-10-24 12:49:34 +0000 UTC (now=2024-10-24 13:46:21.79531473 +0000 UTC))"
2024-10-24T13:46:21.796035610Z I1024 13:46:21.795341       1 tlsconfig.go:181] "Loaded client CA" index=4 certName="client-ca::kube-system::extension-apiserver-authentication::client-ca-file,client-ca::kube-system::extension-apiserver-authentication::requestheader-client-ca-file" certDetail="\"kubelet-bootstrap-kubeconfig-signer\" [] issuer=\"<self>\" (2024-10-24 12:49:32 +0000 UTC to 2034-10-22 12:49:32 +0000 UTC (now=2024-10-24 13:46:21.795335759 +0000 UTC))"
2024-10-24T13:46:21.796035610Z I1024 13:46:21.795358       1 tlsconfig.go:181] "Loaded client CA" index=5 certName="client-ca::kube-system::extension-apiserver-authentication::client-ca-file,client-ca::kube-system::extension-apiserver-authentication::requestheader-client-ca-file" certDetail="\"kube-csr-signer_@1729775012\" [] issuer=\"kubelet-signer\" (2024-10-24 13:03:31 +0000 UTC to 2024-10-25 12:49:34 +0000 UTC (now=2024-10-24 13:46:21.79535289 +0000 UTC))"
2024-10-24T13:46:21.796035610Z I1024 13:46:21.795379       1 tlsconfig.go:181] "Loaded client CA" index=6 certName="client-ca::kube-system::extension-apiserver-authentication::client-ca-file,client-ca::kube-system::extension-apiserver-authentication::requestheader-client-ca-file" certDetail="\"openshift-kube-apiserver-operator_node-system-admin-signer@1729775011\" [] issuer=\"<self>\" (2024-10-24 13:03:30 +0000 UTC to 2025-10-24 13:03:31 +0000 UTC (now=2024-10-24 13:46:21.79537275 +0000 UTC))"
2024-10-24T13:46:21.796035610Z I1024 13:46:21.795398       1 tlsconfig.go:181] "Loaded client CA" index=7 certName="client-ca::kube-system::extension-apiserver-authentication::client-ca-file,client-ca::kube-system::extension-apiserver-authentication::requestheader-client-ca-file" certDetail="\"aggregator-signer\" [] issuer=\"<self>\" (2024-10-24 12:49:32 +0000 UTC to 2024-10-25 12:49:32 +0000 UTC (now=2024-10-24 13:46:21.795392999 +0000 UTC))"
2024-10-24T13:46:21.796035610Z I1024 13:46:21.795429       1 tlsconfig.go:181] "Loaded client CA" index=8 certName="client-ca::kube-system::extension-apiserver-authentication::client-ca-file,client-ca::kube-system::extension-apiserver-authentication::requestheader-client-ca-file" certDetail="\"openshift-kube-apiserver-operator_aggregator-client-signer@1729777579\" [] issuer=\"<self>\" (2024-10-24 13:46:18 +0000 UTC to 2024-10-25 01:46:19 +0000 UTC (now=2024-10-24 13:46:21.79542143 +0000 UTC))"
2024-10-24T13:46:21.796035610Z I1024 13:46:21.795699       1 tlsconfig.go:203] "Loaded serving cert" certName="serving-cert::/etc/kubernetes/static-pod-resources/secrets/serving-cert/tls.crt::/etc/kubernetes/static-pod-resources/secrets/serving-cert/tls.key" certDetail="\"scheduler.openshift-kube-scheduler.svc\" [serving] validServingFor=[scheduler.openshift-kube-scheduler.svc,scheduler.openshift-kube-scheduler.svc.cluster.local] issuer=\"openshift-service-serving-signer@1729775010\" (2024-10-24 13:03:41 +0000 UTC to 2026-10-24 13:03:42 +0000 UTC (now=2024-10-24 13:46:21.795687449 +0000 UTC))"
2024-10-24T13:46:21.800356999Z I1024 13:46:21.800166       1 named_certificates.go:53] "Loaded SNI cert" index=0 certName="self-signed loopback" certDetail="\"apiserver-loopback-client@1729776686\" [serving] validServingFor=[apiserver-loopback-client] issuer=\"apiserver-loopback-client-ca@1729776685\" (2024-10-24 12:31:25 +0000 UTC to 2025-10-24 12:31:25 +0000 UTC (now=2024-10-24 13:46:21.799883439 +0000 UTC))"
2024-10-24T13:46:25.035008997Z I1024 13:46:25.034937       1 schedule_one.go:314] "Successfully bound pod to node" pod="openshift-marketplace/redhat-operators-4vz46" node="ci-op-2fcpj5j6-f6035-2lklf-master-0" evaluatedNodes=6 feasibleNodes=3
2024-10-24T13:46:26.832790438Z I1024 13:46:26.829051       1 schedule_one.go:314] "Successfully bound pod to node" pod="openshift-marketplace/certified-operators-jtb9t" node="ci-op-2fcpj5j6-f6035-2lklf-master-0" evaluatedNodes=6 feasibleNodes=3
2024-10-24T13:46:28.755262749Z I1024 13:46:28.755189       1 schedule_one.go:314] "Successfully bound pod to node" pod="openshift-monitoring/metrics-server-7f98b5f8b5-p26dm" node="ci-op-2fcpj5j6-f6035-2lklf-worker-a-8hj4x" evaluatedNodes=6 feasibleNodes=1
2024-10-24T13:46:28.864022218Z I1024 13:46:28.863926       1 schedule_one.go:1055] "Unable to schedule pod; no fit; waiting" pod="openshift-monitoring/metrics-server-7f98b5f8b5-9v6xq" err="0/6 nodes are available: 3 node(s) didn't match pod anti-affinity rules, 3 node(s) had untolerated taint {node-role.kubernetes.io/master: }. preemption: 0/6 nodes are available: 3 Preemption is not helpful for scheduling, 3 node(s) didn't match pod anti-affinity rules."
2024-10-24T13:46:38.826195847Z I1024 13:46:38.826123       1 schedule_one.go:1055] "Unable to schedule pod; no fit; waiting" pod="openshift-monitoring/metrics-server-7f98b5f8b5-9v6xq" err="0/6 nodes are available: 3 node(s) didn't match pod anti-affinity rules, 3 node(s) had untolerated taint {node-role.kubernetes.io/master: }. preemption: 0/6 nodes are available: 3 Preemption is not helpful for scheduling, 3 node(s) didn't match pod anti-affinity rules."
2024-10-24T13:46:41.305008642Z I1024 13:46:41.304924       1 schedule_one.go:1055] "Unable to schedule pod; no fit; waiting" pod="openshift-monitoring/metrics-server-7f98b5f8b5-9v6xq" err="0/6 nodes are available: 3 node(s) didn't match pod anti-affinity rules, 3 node(s) had untolerated taint {node-role.kubernetes.io/master: }. preemption: 0/6 nodes are available: 3 Preemption is not helpful for scheduling, 3 node(s) didn't match pod anti-affinity rules."
2024-10-24T13:46:52.387501762Z I1024 13:46:52.387412       1 schedule_one.go:1055] "Unable to schedule pod; no fit; waiting" pod="openshift-apiserver/apiserver-678f64f7c9-h6bfx" err="0/6 nodes are available: 3 node(s) didn't match Pod's node affinity/selector, 3 node(s) didn't match pod anti-affinity rules. preemption: 0/6 nodes are available: 3 Preemption is not helpful for scheduling, 3 node(s) didn't match pod anti-affinity rules."
2024-10-24T13:46:52.887076317Z I1024 13:46:52.887012       1 schedule_one.go:1055] "Unable to schedule pod; no fit; waiting" pod="openshift-oauth-apiserver/apiserver-669dcc6dbc-rbnvm" err="0/6 nodes are available: 3 node(s) didn't match Pod's node affinity/selector, 3 node(s) didn't match pod anti-affinity rules. preemption: 0/6 nodes are available: 3 Preemption is not helpful for scheduling, 3 node(s) didn't match pod anti-affinity rules."
2024-10-24T13:47:00.294270942Z I1024 13:47:00.294192       1 schedule_one.go:1055] "Unable to schedule pod; no fit; waiting" pod="openshift-oauth-apiserver/apiserver-65b45c6554-p4w47" err="0/6 nodes are available: 3 node(s) didn't match Pod's node affinity/selector, 3 node(s) didn't match pod anti-affinity rules. preemption: 0/6 nodes are available: 3 Preemption is not helpful for scheduling, 3 node(s) didn't match pod anti-affinity rules."
2024-10-24T13:47:39.987550734Z I1024 13:47:39.987491       1 schedule_one.go:1055] "Unable to schedule pod; no fit; waiting" pod="openshift-apiserver/apiserver-678f64f7c9-h6bfx" err="0/6 nodes are available: 3 node(s) didn't match Pod's node affinity/selector, 3 node(s) didn't match pod anti-affinity rules. preemption: 0/6 nodes are available: 3 Preemption is not helpful for scheduling, 3 node(s) didn't match pod anti-affinity rules."
2024-10-24T13:47:39.988607374Z I1024 13:47:39.988564       1 schedule_one.go:1055] "Unable to schedule pod; no fit; waiting" pod="openshift-oauth-apiserver/apiserver-65b45c6554-p4w47" err="0/6 nodes are available: 3 node(s) didn't match Pod's node affinity/selector, 3 node(s) didn't match pod anti-affinity rules. preemption: 0/6 nodes are available: 3 Preemption is not helpful for scheduling, 3 node(s) didn't match pod anti-affinity rules."
2024-10-24T13:47:39.989057574Z I1024 13:47:39.989015       1 schedule_one.go:1055] "Unable to schedule pod; no fit; waiting" pod="openshift-monitoring/metrics-server-7f98b5f8b5-9v6xq" err="0/6 nodes are available: 3 node(s) didn't match pod anti-affinity rules, 3 node(s) had untolerated taint {node-role.kubernetes.io/master: }. preemption: 0/6 nodes are available: 3 Preemption is not helpful for scheduling, 3 node(s) didn't match pod anti-affinity rules."
2024-10-24T13:47:45.250500011Z I1024 13:47:45.250433       1 schedule_one.go:1055] "Unable to schedule pod; no fit; waiting" pod="openshift-apiserver/apiserver-678f64f7c9-h6bfx" err="0/6 nodes are available: 3 node(s) didn't match Pod's node affinity/selector, 3 node(s) didn't match pod anti-affinity rules. preemption: 0/6 nodes are available: 3 Preemption is not helpful for scheduling, 3 node(s) didn't match pod anti-affinity rules."
2024-10-24T13:47:45.265183591Z I1024 13:47:45.265085       1 schedule_one.go:314] "Successfully bound pod to node" pod="openshift-oauth-apiserver/apiserver-65b45c6554-p4w47" node="ci-op-2fcpj5j6-f6035-2lklf-master-2" evaluatedNodes=6 feasibleNodes=1
2024-10-24T13:47:48.346837259Z I1024 13:47:48.346721       1 schedule_one.go:1055] "Unable to schedule pod; no fit; waiting" pod="openshift-monitoring/metrics-server-7f98b5f8b5-9v6xq" err="0/6 nodes are available: 3 node(s) didn't match pod anti-affinity rules, 3 node(s) had untolerated taint {node-role.kubernetes.io/master: }. preemption: 0/6 nodes are available: 3 Preemption is not helpful for scheduling, 3 node(s) didn't match pod anti-affinity rules."
2024-10-24T13:47:49.348079639Z I1024 13:47:49.347993       1 schedule_one.go:1055] "Unable to schedule pod; no fit; waiting" pod="openshift-apiserver/apiserver-678f64f7c9-h6bfx" err="0/6 nodes are available: 3 node(s) didn't match Pod's node affinity/selector, 3 node(s) didn't match pod anti-affinity rules. preemption: 0/6 nodes are available: 3 Preemption is not helpful for scheduling, 3 node(s) didn't match pod anti-affinity rules."
2024-10-24T13:47:51.183702121Z I1024 13:47:51.183633       1 schedule_one.go:1055] "Unable to schedule pod; no fit; waiting" pod="openshift-oauth-apiserver/apiserver-65b45c6554-tglr4" err="0/6 nodes are available: 3 node(s) didn't match Pod's node affinity/selector, 3 node(s) didn't match pod anti-affinity rules. preemption: 0/6 nodes are available: 3 Preemption is not helpful for scheduling, 3 node(s) didn't match pod anti-affinity rules."
2024-10-24T13:47:53.291282390Z I1024 13:47:53.291214       1 schedule_one.go:1055] "Unable to schedule pod; no fit; waiting" pod="openshift-oauth-apiserver/apiserver-65b45c6554-tglr4" err="0/6 nodes are available: 3 node(s) didn't match Pod's node affinity/selector, 3 node(s) didn't match pod anti-affinity rules. preemption: 0/6 nodes are available: 3 Preemption is not helpful for scheduling, 3 node(s) didn't match pod anti-affinity rules."
2024-10-24T13:47:57.353466459Z I1024 13:47:57.353382       1 schedule_one.go:1055] "Unable to schedule pod; no fit; waiting" pod="openshift-apiserver/apiserver-678f64f7c9-h6bfx" err="0/6 nodes are available: 3 node(s) didn't match Pod's node affinity/selector, 3 node(s) didn't match pod anti-affinity rules. preemption: 0/6 nodes are available: 3 Preemption is not helpful for scheduling, 3 node(s) didn't match pod anti-affinity rules."
2024-10-24T13:47:58.353795659Z I1024 13:47:58.353618       1 schedule_one.go:1055] "Unable to schedule pod; no fit; waiting" pod="openshift-monitoring/metrics-server-7f98b5f8b5-9v6xq" err="0/6 nodes are available: 3 node(s) didn't match pod anti-affinity rules, 3 node(s) had untolerated taint {node-role.kubernetes.io/master: }. preemption: 0/6 nodes are available: 3 Preemption is not helpful for scheduling, 3 node(s) didn't match pod anti-affinity rules."
2024-10-24T13:48:02.785006926Z I1024 13:48:02.784940       1 schedule_one.go:314] "Successfully bound pod to node" pod="openshift-marketplace/community-operators-l2rlg" node="ci-op-2fcpj5j6-f6035-2lklf-master-2" evaluatedNodes=6 feasibleNodes=3
2024-10-24T13:48:15.536804168Z I1024 13:48:15.536720       1 schedule_one.go:1055] "Unable to schedule pod; no fit; waiting" pod="openshift-oauth-apiserver/apiserver-65b45c6554-tglr4" err="0/6 nodes are available: 3 node(s) didn't match Pod's node affinity/selector, 3 node(s) didn't match pod anti-affinity rules. preemption: 0/6 nodes are available: 3 Preemption is not helpful for scheduling, 3 node(s) didn't match pod anti-affinity rules."
2024-10-24T13:48:15.537548698Z I1024 13:48:15.537519       1 schedule_one.go:1055] "Unable to schedule pod; no fit; waiting" pod="openshift-apiserver/apiserver-678f64f7c9-h6bfx" err="0/6 nodes are available: 3 node(s) didn't match Pod's node affinity/selector, 3 node(s) didn't match pod anti-affinity rules. preemption: 0/6 nodes are available: 3 Preemption is not helpful for scheduling, 3 node(s) didn't match pod anti-affinity rules."
2024-10-24T13:48:15.538080747Z I1024 13:48:15.538023       1 schedule_one.go:1055] "Unable to schedule pod; no fit; waiting" pod="openshift-monitoring/metrics-server-7f98b5f8b5-9v6xq" err="0/6 nodes are available: 3 node(s) didn't match pod anti-affinity rules, 3 node(s) had untolerated taint {node-role.kubernetes.io/master: }. preemption: 0/6 nodes are available: 3 Preemption is not helpful for scheduling, 3 node(s) didn't match pod anti-affinity rules."
2024-10-24T13:48:27.263840760Z I1024 13:48:27.263727       1 schedule_one.go:1055] "Unable to schedule pod; no fit; waiting" pod="openshift-oauth-apiserver/apiserver-65b45c6554-tglr4" err="0/6 nodes are available: 3 node(s) didn't match Pod's node affinity/selector, 3 node(s) didn't match pod anti-affinity rules. preemption: 0/6 nodes are available: 3 Preemption is not helpful for scheduling, 3 node(s) didn't match pod anti-affinity rules."
2024-10-24T13:48:27.264789960Z I1024 13:48:27.264732       1 schedule_one.go:1055] "Unable to schedule pod; no fit; waiting" pod="openshift-apiserver/apiserver-678f64f7c9-h6bfx" err="0/6 nodes are available: 3 node(s) didn't match Pod's node affinity/selector, 3 node(s) didn't match pod anti-affinity rules. preemption: 0/6 nodes are available: 3 Preemption is not helpful for scheduling, 3 node(s) didn't match pod anti-affinity rules."
2024-10-24T13:48:27.265546130Z I1024 13:48:27.265460       1 schedule_one.go:1055] "Unable to schedule pod; no fit; waiting" pod="openshift-monitoring/metrics-server-7f98b5f8b5-9v6xq" err="0/6 nodes are available: 3 node(s) didn't match pod anti-affinity rules, 3 node(s) had untolerated taint {node-role.kubernetes.io/master: }. preemption: 0/6 nodes are available: 3 Preemption is not helpful for scheduling, 3 node(s) didn't match pod anti-affinity rules."
2024-10-24T13:48:35.375230982Z I1024 13:48:35.375148       1 schedule_one.go:1055] "Unable to schedule pod; no fit; waiting" pod="openshift-oauth-apiserver/apiserver-65b45c6554-tglr4" err="0/6 nodes are available: 3 node(s) didn't match Pod's node affinity/selector, 3 node(s) didn't match pod anti-affinity rules. preemption: 0/6 nodes are available: 3 Preemption is not helpful for scheduling, 3 node(s) didn't match pod anti-affinity rules."
2024-10-24T13:48:37.376384563Z I1024 13:48:37.376303       1 schedule_one.go:1055] "Unable to schedule pod; no fit; waiting" pod="openshift-apiserver/apiserver-678f64f7c9-h6bfx" err="0/6 nodes are available: 3 node(s) didn't match Pod's node affinity/selector, 3 node(s) didn't match pod anti-affinity rules. preemption: 0/6 nodes are available: 3 Preemption is not helpful for scheduling, 3 node(s) didn't match pod anti-affinity rules."
2024-10-24T13:48:37.376908763Z I1024 13:48:37.376869       1 schedule_one.go:1055] "Unable to schedule pod; no fit; waiting" pod="openshift-monitoring/metrics-server-7f98b5f8b5-9v6xq" err="0/6 nodes are available: 3 node(s) didn't match pod anti-affinity rules, 3 node(s) had untolerated taint {node-role.kubernetes.io/master: }. preemption: 0/6 nodes are available: 3 Preemption is not helpful for scheduling, 3 node(s) didn't match pod anti-affinity rules."
2024-10-24T13:48:45.391320709Z I1024 13:48:45.391114       1 schedule_one.go:314] "Successfully bound pod to node" pod="openshift-oauth-apiserver/apiserver-65b45c6554-tglr4" node="ci-op-2fcpj5j6-f6035-2lklf-master-0" evaluatedNodes=6 feasibleNodes=1
2024-10-24T13:48:47.381893343Z I1024 13:48:47.381827       1 schedule_one.go:1055] "Unable to schedule pod; no fit; waiting" pod="openshift-monitoring/metrics-server-7f98b5f8b5-9v6xq" err="0/6 nodes are available: 3 node(s) didn't match pod anti-affinity rules, 3 node(s) had untolerated taint {node-role.kubernetes.io/master: }. preemption: 0/6 nodes are available: 3 Preemption is not helpful for scheduling, 3 node(s) didn't match pod anti-affinity rules."
2024-10-24T13:48:47.392450863Z I1024 13:48:47.392387       1 schedule_one.go:314] "Successfully bound pod to node" pod="openshift-apiserver/apiserver-678f64f7c9-h6bfx" node="ci-op-2fcpj5j6-f6035-2lklf-master-2" evaluatedNodes=6 feasibleNodes=1
2024-10-24T13:48:51.311418444Z I1024 13:48:51.311354       1 schedule_one.go:1055] "Unable to schedule pod; no fit; waiting" pod="openshift-oauth-apiserver/apiserver-65b45c6554-984d7" err="0/6 nodes are available: 3 node(s) didn't match Pod's node affinity/selector, 3 node(s) didn't match pod anti-affinity rules. preemption: 0/6 nodes are available: 3 Preemption is not helpful for scheduling, 3 node(s) didn't match pod anti-affinity rules."
2024-10-24T13:48:53.571820410Z I1024 13:48:53.571730       1 schedule_one.go:1055] "Unable to schedule pod; no fit; waiting" pod="openshift-apiserver/apiserver-678f64f7c9-qqtmg" err="0/6 nodes are available: 3 node(s) didn't match Pod's node affinity/selector, 3 node(s) didn't match pod anti-affinity rules. preemption: 0/6 nodes are available: 3 Preemption is not helpful for scheduling, 3 node(s) didn't match pod anti-affinity rules."
2024-10-24T13:48:59.515674449Z I1024 13:48:59.515613       1 schedule_one.go:1055] "Unable to schedule pod; no fit; waiting" pod="openshift-oauth-apiserver/apiserver-65b45c6554-984d7" err="0/6 nodes are available: 3 node(s) didn't match Pod's node affinity/selector, 3 node(s) didn't match pod anti-affinity rules. preemption: 0/6 nodes are available: 3 Preemption is not helpful for scheduling, 3 node(s) didn't match pod anti-affinity rules."
2024-10-24T13:48:59.516628928Z I1024 13:48:59.516589       1 schedule_one.go:1055] "Unable to schedule pod; no fit; waiting" pod="openshift-apiserver/apiserver-678f64f7c9-qqtmg" err="0/6 nodes are available: 3 node(s) didn't match Pod's node affinity/selector, 3 node(s) didn't match pod anti-affinity rules. preemption: 0/6 nodes are available: 3 Preemption is not helpful for scheduling, 3 node(s) didn't match pod anti-affinity rules."
2024-10-24T13:48:59.528938849Z I1024 13:48:59.528877       1 schedule_one.go:314] "Successfully bound pod to node" pod="openshift-monitoring/metrics-server-7f98b5f8b5-9v6xq" node="ci-op-2fcpj5j6-f6035-2lklf-worker-c-z8hfz" evaluatedNodes=6 feasibleNodes=1
2024-10-24T13:49:38.686407319Z I1024 13:49:38.686337       1 schedule_one.go:1055] "Unable to schedule pod; no fit; waiting" pod="openshift-oauth-apiserver/apiserver-65b45c6554-984d7" err="0/6 nodes are available: 3 node(s) didn't match Pod's node affinity/selector, 3 node(s) didn't match pod anti-affinity rules. preemption: 0/6 nodes are available: 3 Preemption is not helpful for scheduling, 3 node(s) didn't match pod anti-affinity rules."
2024-10-24T13:49:38.687999269Z I1024 13:49:38.687891       1 schedule_one.go:1055] "Unable to schedule pod; no fit; waiting" pod="openshift-apiserver/apiserver-678f64f7c9-qqtmg" err="0/6 nodes are available: 3 node(s) didn't match Pod's node affinity/selector, 3 node(s) didn't match pod anti-affinity rules. preemption: 0/6 nodes are available: 3 Preemption is not helpful for scheduling, 3 node(s) didn't match pod anti-affinity rules."
2024-10-24T13:49:43.415889160Z I1024 13:49:43.415788       1 schedule_one.go:1055] "Unable to schedule pod; no fit; waiting" pod="openshift-oauth-apiserver/apiserver-65b45c6554-984d7" err="0/6 nodes are available: 3 node(s) didn't match Pod's node affinity/selector, 3 node(s) didn't match pod anti-affinity rules. preemption: 0/6 nodes are available: 3 Preemption is not helpful for scheduling, 3 node(s) didn't match pod anti-affinity rules."
2024-10-24T13:49:43.416720261Z I1024 13:49:43.416673       1 schedule_one.go:1055] "Unable to schedule pod; no fit; waiting" pod="openshift-apiserver/apiserver-678f64f7c9-qqtmg" err="0/6 nodes are available: 3 node(s) didn't match Pod's node affinity/selector, 3 node(s) didn't match pod anti-affinity rules. preemption: 0/6 nodes are available: 3 Preemption is not helpful for scheduling, 3 node(s) didn't match pod anti-affinity rules."
2024-10-24T13:49:51.422486009Z I1024 13:49:51.422419       1 schedule_one.go:1055] "Unable to schedule pod; no fit; waiting" pod="openshift-apiserver/apiserver-678f64f7c9-qqtmg" err="0/6 nodes are available: 3 node(s) didn't match Pod's node affinity/selector, 3 node(s) didn't match pod anti-affinity rules. preemption: 0/6 nodes are available: 3 Preemption is not helpful for scheduling, 3 node(s) didn't match pod anti-affinity rules."
2024-10-24T13:49:51.433239799Z I1024 13:49:51.433177       1 schedule_one.go:314] "Successfully bound pod to node" pod="openshift-oauth-apiserver/apiserver-65b45c6554-984d7" node="ci-op-2fcpj5j6-f6035-2lklf-master-1" evaluatedNodes=6 feasibleNodes=1
2024-10-24T13:50:29.845832124Z I1024 13:50:29.845740       1 schedule_one.go:1055] "Unable to schedule pod; no fit; waiting" pod="openshift-oauth-apiserver/apiserver-6d668d4fc7-q9mjb" err="0/6 nodes are available: 3 node(s) didn't match Pod's node affinity/selector, 3 node(s) didn't match pod anti-affinity rules. preemption: 0/6 nodes are available: 3 Preemption is not helpful for scheduling, 3 node(s) didn't match pod anti-affinity rules."
2024-10-24T13:50:43.920421071Z I1024 13:50:43.920331       1 schedule_one.go:1055] "Unable to schedule pod; no fit; waiting" pod="openshift-oauth-apiserver/apiserver-6d668d4fc7-q9mjb" err="0/6 nodes are available: 3 node(s) didn't match Pod's node affinity/selector, 3 node(s) didn't match pod anti-affinity rules. preemption: 0/6 nodes are available: 3 Preemption is not helpful for scheduling, 3 node(s) didn't match pod anti-affinity rules."
2024-10-24T13:50:43.932745061Z I1024 13:50:43.932651       1 schedule_one.go:314] "Successfully bound pod to node" pod="openshift-apiserver/apiserver-678f64f7c9-qqtmg" node="ci-op-2fcpj5j6-f6035-2lklf-master-0" evaluatedNodes=6 feasibleNodes=1
2024-10-24T13:50:54.507438893Z I1024 13:50:54.506975       1 schedule_one.go:1055] "Unable to schedule pod; no fit; waiting" pod="openshift-apiserver/apiserver-678f64f7c9-lh9lm" err="0/6 nodes are available: 3 node(s) didn't match Pod's node affinity/selector, 3 node(s) didn't match pod anti-affinity rules. preemption: 0/6 nodes are available: 3 Preemption is not helpful for scheduling, 3 node(s) didn't match pod anti-affinity rules."
2024-10-24T13:51:03.176288035Z I1024 13:51:03.176224       1 schedule_one.go:1055] "Unable to schedule pod; no fit; waiting" pod="openshift-oauth-apiserver/apiserver-6d668d4fc7-q9mjb" err="0/6 nodes are available: 3 node(s) didn't match Pod's node affinity/selector, 3 node(s) didn't match pod anti-affinity rules. preemption: 0/6 nodes are available: 3 Preemption is not helpful for scheduling, 3 node(s) didn't match pod anti-affinity rules."
2024-10-24T13:51:03.177952505Z I1024 13:51:03.177842       1 schedule_one.go:1055] "Unable to schedule pod; no fit; waiting" pod="openshift-apiserver/apiserver-678f64f7c9-lh9lm" err="0/6 nodes are available: 3 node(s) didn't match Pod's node affinity/selector, 3 node(s) didn't match pod anti-affinity rules. preemption: 0/6 nodes are available: 3 Preemption is not helpful for scheduling, 3 node(s) didn't match pod anti-affinity rules."
2024-10-24T13:51:16.436677169Z I1024 13:51:16.436598       1 schedule_one.go:314] "Successfully bound pod to node" pod="openshift-marketplace/redhat-marketplace-4q6c9" node="ci-op-2fcpj5j6-f6035-2lklf-master-2" evaluatedNodes=6 feasibleNodes=3
2024-10-24T13:51:21.275113550Z I1024 13:51:21.275018       1 schedule_one.go:1055] "Unable to schedule pod; no fit; waiting" pod="openshift-apiserver/apiserver-678f64f7c9-lh9lm" err="0/6 nodes are available: 3 node(s) didn't match Pod's node affinity/selector, 3 node(s) didn't match pod anti-affinity rules. preemption: 0/6 nodes are available: 3 Preemption is not helpful for scheduling, 3 node(s) didn't match pod anti-affinity rules."
2024-10-24T13:51:21.283731980Z I1024 13:51:21.283663       1 schedule_one.go:314] "Successfully bound pod to node" pod="openshift-oauth-apiserver/apiserver-6d668d4fc7-q9mjb" node="ci-op-2fcpj5j6-f6035-2lklf-master-1" evaluatedNodes=6 feasibleNodes=1
2024-10-24T13:51:27.739852164Z I1024 13:51:27.739712       1 schedule_one.go:1055] "Unable to schedule pod; no fit; waiting" pod="openshift-oauth-apiserver/apiserver-6d668d4fc7-d9msv" err="0/6 nodes are available: 3 node(s) didn't match Pod's node affinity/selector, 3 node(s) didn't match pod anti-affinity rules. preemption: 0/6 nodes are available: 3 Preemption is not helpful for scheduling, 3 node(s) didn't match pod anti-affinity rules."
2024-10-24T13:51:30.590430764Z I1024 13:51:30.590370       1 schedule_one.go:1055] "Unable to schedule pod; no fit; waiting" pod="openshift-apiserver/apiserver-678f64f7c9-lh9lm" err="0/6 nodes are available: 3 node(s) didn't match Pod's node affinity/selector, 3 node(s) didn't match pod anti-affinity rules. preemption: 0/6 nodes are available: 3 Preemption is not helpful for scheduling, 3 node(s) didn't match pod anti-affinity rules."
2024-10-24T13:51:30.591490755Z I1024 13:51:30.591422       1 schedule_one.go:1055] "Unable to schedule pod; no fit; waiting" pod="openshift-oauth-apiserver/apiserver-6d668d4fc7-d9msv" err="0/6 nodes are available: 3 node(s) didn't match Pod's node affinity/selector, 3 node(s) didn't match pod anti-affinity rules. preemption: 0/6 nodes are available: 3 Preemption is not helpful for scheduling, 3 node(s) didn't match pod anti-affinity rules."
2024-10-24T13:52:20.149829380Z I1024 13:52:20.149321       1 schedule_one.go:1055] "Unable to schedule pod; no fit; waiting" pod="openshift-apiserver/apiserver-678f64f7c9-lh9lm" err="0/6 nodes are available: 3 node(s) didn't match Pod's node affinity/selector, 3 node(s) didn't match pod anti-affinity rules. preemption: 0/6 nodes are available: 3 Preemption is not helpful for scheduling, 3 node(s) didn't match pod anti-affinity rules."
2024-10-24T13:52:20.161445560Z I1024 13:52:20.161376       1 schedule_one.go:314] "Successfully bound pod to node" pod="openshift-oauth-apiserver/apiserver-6d668d4fc7-d9msv" node="ci-op-2fcpj5j6-f6035-2lklf-master-2" evaluatedNodes=6 feasibleNodes=1
2024-10-24T13:52:25.704084933Z I1024 13:52:25.703995       1 schedule_one.go:1055] "Unable to schedule pod; no fit; waiting" pod="openshift-oauth-apiserver/apiserver-6d668d4fc7-x2q4p" err="0/6 nodes are available: 3 node(s) didn't match Pod's node affinity/selector, 3 node(s) didn't match pod anti-affinity rules. preemption: 0/6 nodes are available: 3 Preemption is not helpful for scheduling, 3 node(s) didn't match pod anti-affinity rules."
2024-10-24T13:52:44.837840408Z I1024 13:52:44.832575       1 schedule_one.go:1055] "Unable to schedule pod; no fit; waiting" pod="openshift-oauth-apiserver/apiserver-6d668d4fc7-x2q4p" err="0/6 nodes are available: 3 node(s) didn't match Pod's node affinity/selector, 3 node(s) didn't match pod anti-affinity rules. preemption: 0/6 nodes are available: 3 Preemption is not helpful for scheduling, 3 node(s) didn't match pod anti-affinity rules."
2024-10-24T13:52:44.845691478Z I1024 13:52:44.845629       1 schedule_one.go:314] "Successfully bound pod to node" pod="openshift-apiserver/apiserver-678f64f7c9-lh9lm" node="ci-op-2fcpj5j6-f6035-2lklf-master-1" evaluatedNodes=6 feasibleNodes=1
2024-10-24T13:53:00.428288640Z I1024 13:53:00.428208       1 schedule_one.go:1055] "Unable to schedule pod; no fit; waiting" pod="openshift-oauth-apiserver/apiserver-6d668d4fc7-x2q4p" err="0/6 nodes are available: 3 node(s) didn't match Pod's node affinity/selector, 3 node(s) didn't match pod anti-affinity rules. preemption: 0/6 nodes are available: 3 Preemption is not helpful for scheduling, 3 node(s) didn't match pod anti-affinity rules."
2024-10-24T13:53:18.064529985Z I1024 13:53:18.064462       1 schedule_one.go:314] "Successfully bound pod to node" pod="openshift-oauth-apiserver/apiserver-6d668d4fc7-x2q4p" node="ci-op-2fcpj5j6-f6035-2lklf-master-0" evaluatedNodes=6 feasibleNodes=1
2024-10-24T13:53:23.154681878Z I1024 13:53:23.154599       1 schedule_one.go:1055] "Unable to schedule pod; no fit; waiting" pod="openshift-apiserver/apiserver-6545b7bd68-hjg8d" err="0/6 nodes are available: 3 node(s) didn't match Pod's node affinity/selector, 3 node(s) didn't match pod anti-affinity rules. preemption: 0/6 nodes are available: 3 Preemption is not helpful for scheduling, 3 node(s) didn't match pod anti-affinity rules."
2024-10-24T13:54:14.311625024Z I1024 13:54:14.311566       1 schedule_one.go:1055] "Unable to schedule pod; no fit; waiting" pod="openshift-apiserver/apiserver-6545b7bd68-hjg8d" err="0/6 nodes are available: 3 node(s) didn't match Pod's node affinity/selector, 3 node(s) didn't match pod anti-affinity rules. preemption: 0/6 nodes are available: 3 Preemption is not helpful for scheduling, 3 node(s) didn't match pod anti-affinity rules."
2024-10-24T13:54:16.602895954Z I1024 13:54:16.602836       1 schedule_one.go:314] "Successfully bound pod to node" pod="openshift-apiserver/apiserver-6545b7bd68-hjg8d" node="ci-op-2fcpj5j6-f6035-2lklf-master-1" evaluatedNodes=6 feasibleNodes=1
2024-10-24T13:54:22.881224729Z I1024 13:54:22.881162       1 schedule_one.go:1055] "Unable to schedule pod; no fit; waiting" pod="openshift-apiserver/apiserver-6545b7bd68-wnbqx" err="0/6 nodes are available: 3 node(s) didn't match Pod's node affinity/selector, 3 node(s) didn't match pod anti-affinity rules. preemption: 0/6 nodes are available: 3 Preemption is not helpful for scheduling, 3 node(s) didn't match pod anti-affinity rules."
2024-10-24T13:56:11.059922412Z I1024 13:56:11.059743       1 schedule_one.go:1055] "Unable to schedule pod; no fit; waiting" pod="openshift-apiserver/apiserver-6545b7bd68-wnbqx" err="0/6 nodes are available: 3 node(s) didn't match Pod's node affinity/selector, 3 node(s) didn't match pod anti-affinity rules. preemption: 0/6 nodes are available: 3 Preemption is not helpful for scheduling, 3 node(s) didn't match pod anti-affinity rules."
2024-10-24T13:56:13.243848119Z I1024 13:56:13.243765       1 schedule_one.go:314] "Successfully bound pod to node" pod="openshift-apiserver/apiserver-6545b7bd68-wnbqx" node="ci-op-2fcpj5j6-f6035-2lklf-master-0" evaluatedNodes=6 feasibleNodes=1
2024-10-24T13:56:18.995445709Z I1024 13:56:18.995357       1 schedule_one.go:1055] "Unable to schedule pod; no fit; waiting" pod="openshift-apiserver/apiserver-6545b7bd68-jsb4b" err="0/6 nodes are available: 3 node(s) didn't match Pod's node affinity/selector, 3 node(s) didn't match pod anti-affinity rules. preemption: 0/6 nodes are available: 3 Preemption is not helpful for scheduling, 3 node(s) didn't match pod anti-affinity rules."
2024-10-24T13:57:17.857846514Z I1024 13:57:17.857720       1 schedule_one.go:314] "Successfully bound pod to node" pod="openshift-marketplace/certified-operators-8dppf" node="ci-op-2fcpj5j6-f6035-2lklf-master-0" evaluatedNodes=6 feasibleNodes=3
2024-10-24T13:57:21.965164241Z I1024 13:57:21.965013       1 schedule_one.go:314] "Successfully bound pod to node" pod="openshift-apiserver/apiserver-6545b7bd68-jsb4b" node="ci-op-2fcpj5j6-f6035-2lklf-master-2" evaluatedNodes=6 feasibleNodes=1
2024-10-24T13:57:36.877535011Z I1024 13:57:36.877428       1 schedule_one.go:314] "Successfully bound pod to node" pod="openshift-marketplace/redhat-operators-lmrfh" node="ci-op-2fcpj5j6-f6035-2lklf-master-0" evaluatedNodes=6 feasibleNodes=3
2024-10-24T13:59:16.541542207Z I1024 13:59:16.541431       1 schedule_one.go:314] "Successfully bound pod to node" pod="openshift-marketplace/community-operators-s6thr" node="ci-op-2fcpj5j6-f6035-2lklf-master-2" evaluatedNodes=6 feasibleNodes=3
2024-10-24T14:00:00.181442555Z I1024 14:00:00.181354       1 schedule_one.go:314] "Successfully bound pod to node" pod="openshift-operator-lifecycle-manager/collect-profiles-28829640-fvzjr" node="ci-op-2fcpj5j6-f6035-2lklf-worker-a-8hj4x" evaluatedNodes=6 feasibleNodes=3
2024-10-24T14:01:17.836191944Z I1024 14:01:17.835727       1 schedule_one.go:314] "Successfully bound pod to node" pod="openshift-marketplace/redhat-marketplace-2p9x6" node="ci-op-2fcpj5j6-f6035-2lklf-master-2" evaluatedNodes=6 feasibleNodes=3
2024-10-24T14:07:56.025974183Z I1024 14:07:56.025903       1 schedule_one.go:314] "Successfully bound pod to node" pod="openshift-console/console-6db848448f-lt54s" node="ci-op-2fcpj5j6-f6035-2lklf-master-1" evaluatedNodes=6 feasibleNodes=1
2024-10-24T14:07:56.028697033Z I1024 14:07:56.028589       1 schedule_one.go:1055] "Unable to schedule pod; no fit; waiting" pod="openshift-console/console-6db848448f-kcnxq" err="0/6 nodes are available: 3 node(s) didn't match Pod's node affinity/selector, 3 node(s) didn't match pod anti-affinity rules. preemption: 0/6 nodes are available: 3 Preemption is not helpful for scheduling, 3 node(s) didn't match pod anti-affinity rules."
2024-10-24T14:07:56.191450632Z I1024 14:07:56.191330       1 schedule_one.go:1055] "Unable to schedule pod; no fit; waiting" pod="openshift-console/console-6689f89885-m729m" err="0/6 nodes are available: 3 node(s) didn't match Pod's node affinity/selector, 3 node(s) didn't match pod anti-affinity rules. preemption: 0/6 nodes are available: 3 Preemption is not helpful for scheduling, 3 node(s) didn't match pod anti-affinity rules."
2024-10-24T14:07:56.228089952Z I1024 14:07:56.228020       1 schedule_one.go:1055] "Unable to schedule pod; no fit; waiting" pod="openshift-console/console-6689f89885-9kjdn" err="0/6 nodes are available: 3 node(s) didn't match Pod's node affinity/selector, 3 node(s) didn't match pod anti-affinity rules. preemption: 0/6 nodes are available: 3 Preemption is not helpful for scheduling, 3 node(s) didn't match pod anti-affinity rules."
2024-10-24T14:07:56.790806751Z I1024 14:07:56.790214       1 schedule_one.go:1055] "Unable to schedule pod; no fit; waiting" pod="openshift-controller-manager/controller-manager-69b9cd8b79-2w8mk" err="0/6 nodes are available: 3 node(s) didn't match Pod's node affinity/selector, 3 node(s) didn't match pod anti-affinity rules. preemption: 0/6 nodes are available: 3 Preemption is not helpful for scheduling, 3 node(s) didn't match pod anti-affinity rules."
2024-10-24T14:07:57.371493649Z I1024 14:07:57.371431       1 schedule_one.go:1055] "Unable to schedule pod; no fit; waiting" pod="openshift-authentication/oauth-openshift-c84b6d8c7-9l5gh" err="0/6 nodes are available: 3 node(s) didn't match Pod's node affinity/selector, 3 node(s) didn't match pod anti-affinity rules. preemption: 0/6 nodes are available: 3 Preemption is not helpful for scheduling, 3 node(s) didn't match pod anti-affinity rules."
2024-10-24T14:07:58.081958717Z I1024 14:07:58.081873       1 schedule_one.go:1055] "Unable to schedule pod; no fit; waiting" pod="openshift-console/console-6689f89885-9kjdn" err="0/6 nodes are available: 3 node(s) didn't match Pod's node affinity/selector, 3 node(s) didn't match pod anti-affinity rules. preemption: 0/6 nodes are available: 3 Preemption is not helpful for scheduling, 3 node(s) didn't match pod anti-affinity rules."
2024-10-24T14:07:58.096125297Z I1024 14:07:58.096052       1 schedule_one.go:314] "Successfully bound pod to node" pod="openshift-console/console-6689f89885-m729m" node="ci-op-2fcpj5j6-f6035-2lklf-master-1" evaluatedNodes=6 feasibleNodes=1
2024-10-24T14:07:58.096602807Z I1024 14:07:58.096521       1 schedule_one.go:314] "Successfully bound pod to node" pod="openshift-controller-manager/controller-manager-69b9cd8b79-2w8mk" node="ci-op-2fcpj5j6-f6035-2lklf-master-2" evaluatedNodes=6 feasibleNodes=1
2024-10-24T14:07:59.081326004Z I1024 14:07:59.081249       1 schedule_one.go:1055] "Unable to schedule pod; no fit; waiting" pod="openshift-authentication/oauth-openshift-c84b6d8c7-9l5gh" err="0/6 nodes are available: 3 node(s) didn't match Pod's node affinity/selector, 3 node(s) didn't match pod anti-affinity rules. preemption: 0/6 nodes are available: 3 Preemption is not helpful for scheduling, 3 node(s) didn't match pod anti-affinity rules."
2024-10-24T14:07:59.954640912Z I1024 14:07:59.954573       1 schedule_one.go:1055] "Unable to schedule pod; no fit; waiting" pod="openshift-controller-manager/controller-manager-69b9cd8b79-6kfgx" err="0/6 nodes are available: 3 node(s) didn't match Pod's node affinity/selector, 3 node(s) didn't match pod anti-affinity rules. preemption: 0/6 nodes are available: 3 Preemption is not helpful for scheduling, 3 node(s) didn't match pod anti-affinity rules."
2024-10-24T14:08:00.466654421Z I1024 14:08:00.466580       1 schedule_one.go:1055] "Unable to schedule pod; no fit; waiting" pod="openshift-console/console-6689f89885-9kjdn" err="0/6 nodes are available: 3 node(s) didn't match Pod's node affinity/selector, 3 node(s) didn't match pod anti-affinity rules. preemption: 0/6 nodes are available: 3 Preemption is not helpful for scheduling, 3 node(s) didn't match pod anti-affinity rules."
2024-10-24T14:08:01.083493349Z I1024 14:08:01.083400       1 schedule_one.go:1055] "Unable to schedule pod; no fit; waiting" pod="openshift-authentication/oauth-openshift-c84b6d8c7-9l5gh" err="0/6 nodes are available: 3 node(s) didn't match Pod's node affinity/selector, 3 node(s) didn't match pod anti-affinity rules. preemption: 0/6 nodes are available: 3 Preemption is not helpful for scheduling, 3 node(s) didn't match pod anti-affinity rules."
2024-10-24T14:08:01.099314649Z I1024 14:08:01.099215       1 schedule_one.go:314] "Successfully bound pod to node" pod="openshift-controller-manager/controller-manager-69b9cd8b79-6kfgx" node="ci-op-2fcpj5j6-f6035-2lklf-master-0" evaluatedNodes=6 feasibleNodes=1
2024-10-24T14:08:03.192441163Z I1024 14:08:03.192364       1 schedule_one.go:1055] "Unable to schedule pod; no fit; waiting" pod="openshift-controller-manager/controller-manager-69b9cd8b79-cwcp4" err="0/6 nodes are available: 3 node(s) didn't match Pod's node affinity/selector, 3 node(s) didn't match pod anti-affinity rules. preemption: 0/6 nodes are available: 3 Preemption is not helpful for scheduling, 3 node(s) didn't match pod anti-affinity rules."
2024-10-24T14:08:04.882510419Z I1024 14:08:04.882417       1 schedule_one.go:314] "Successfully bound pod to node" pod="openshift-multus/cni-sysctl-allowlist-ds-cqvsc" node="ci-op-2fcpj5j6-f6035-2lklf-worker-a-8hj4x" evaluatedNodes=1 feasibleNodes=1
2024-10-24T14:08:04.900655939Z I1024 14:08:04.899970       1 schedule_one.go:314] "Successfully bound pod to node" pod="openshift-multus/cni-sysctl-allowlist-ds-jdfxk" node="ci-op-2fcpj5j6-f6035-2lklf-worker-b-hj8l2" evaluatedNodes=1 feasibleNodes=1
2024-10-24T14:08:04.902297609Z I1024 14:08:04.902240       1 schedule_one.go:314] "Successfully bound pod to node" pod="openshift-multus/cni-sysctl-allowlist-ds-gbw9t" node="ci-op-2fcpj5j6-f6035-2lklf-worker-c-z8hfz" evaluatedNodes=1 feasibleNodes=1
2024-10-24T14:08:05.086450799Z I1024 14:08:05.086357       1 schedule_one.go:1055] "Unable to schedule pod; no fit; waiting" pod="openshift-console/console-6689f89885-9kjdn" err="0/6 nodes are available: 3 node(s) didn't match Pod's node affinity/selector, 3 node(s) didn't match pod anti-affinity rules. preemption: 0/6 nodes are available: 3 Preemption is not helpful for scheduling, 3 node(s) didn't match pod anti-affinity rules."
2024-10-24T14:08:05.087489968Z I1024 14:08:05.087431       1 schedule_one.go:1055] "Unable to schedule pod; no fit; waiting" pod="openshift-authentication/oauth-openshift-c84b6d8c7-9l5gh" err="0/6 nodes are available: 3 node(s) didn't match Pod's node affinity/selector, 3 node(s) didn't match pod anti-affinity rules. preemption: 0/6 nodes are available: 3 Preemption is not helpful for scheduling, 3 node(s) didn't match pod anti-affinity rules."
2024-10-24T14:08:05.097962298Z I1024 14:08:05.097846       1 schedule_one.go:314] "Successfully bound pod to node" pod="openshift-controller-manager/controller-manager-69b9cd8b79-cwcp4" node="ci-op-2fcpj5j6-f6035-2lklf-master-1" evaluatedNodes=6 feasibleNodes=1
2024-10-24T14:08:10.855501946Z I1024 14:08:10.854868       1 schedule_one.go:1055] "Unable to schedule pod; no fit; waiting" pod="openshift-console/console-bf6f6f7f6-lk9bc" err="0/6 nodes are available: 3 node(s) didn't match Pod's node affinity/selector, 3 node(s) didn't match pod anti-affinity rules. preemption: 0/6 nodes are available: 3 Preemption is not helpful for scheduling, 3 node(s) didn't match pod anti-affinity rules."
2024-10-24T14:08:10.875887386Z I1024 14:08:10.875797       1 schedule_one.go:1055] "Unable to schedule pod; no fit; waiting" pod="openshift-console/console-bf6f6f7f6-bl5sv" err="0/6 nodes are available: 3 node(s) didn't match Pod's node affinity/selector, 3 node(s) didn't match pod anti-affinity rules. preemption: 0/6 nodes are available: 3 Preemption is not helpful for scheduling, 3 node(s) didn't match pod anti-affinity rules."
2024-10-24T14:08:16.515587756Z I1024 14:08:16.515507       1 schedule_one.go:1055] "Unable to schedule pod; no fit; waiting" pod="openshift-route-controller-manager/route-controller-manager-5486b44d46-6mvfq" err="0/6 nodes are available: 3 node(s) didn't match Pod's node affinity/selector, 3 node(s) didn't match pod anti-affinity rules. preemption: 0/6 nodes are available: 3 Preemption is not helpful for scheduling, 3 node(s) didn't match pod anti-affinity rules."
2024-10-24T14:08:16.846288416Z I1024 14:08:16.846209       1 schedule_one.go:1055] "Unable to schedule pod; no fit; waiting" pod="openshift-authentication/oauth-openshift-c84b6d8c7-9l5gh" err="0/6 nodes are available: 3 node(s) didn't match Pod's node affinity/selector, 3 node(s) didn't match pod anti-affinity rules. preemption: 0/6 nodes are available: 3 Preemption is not helpful for scheduling, 3 node(s) didn't match pod anti-affinity rules."
2024-10-24T14:08:16.846976676Z I1024 14:08:16.846895       1 schedule_one.go:1055] "Unable to schedule pod; no fit; waiting" pod="openshift-console/console-bf6f6f7f6-lk9bc" err="0/6 nodes are available: 3 node(s) didn't match Pod's node affinity/selector, 3 node(s) didn't match pod anti-affinity rules. preemption: 0/6 nodes are available: 3 Preemption is not helpful for scheduling, 3 node(s) didn't match pod anti-affinity rules."
2024-10-24T14:08:16.847595855Z I1024 14:08:16.847524       1 schedule_one.go:1055] "Unable to schedule pod; no fit; waiting" pod="openshift-console/console-bf6f6f7f6-bl5sv" err="0/6 nodes are available: 3 node(s) didn't match Pod's node affinity/selector, 3 node(s) didn't match pod anti-affinity rules. preemption: 0/6 nodes are available: 3 Preemption is not helpful for scheduling, 3 node(s) didn't match pod anti-affinity rules."
2024-10-24T14:08:18.107844236Z I1024 14:08:18.107701       1 schedule_one.go:314] "Successfully bound pod to node" pod="openshift-route-controller-manager/route-controller-manager-5486b44d46-6mvfq" node="ci-op-2fcpj5j6-f6035-2lklf-master-2" evaluatedNodes=6 feasibleNodes=1
2024-10-24T14:08:20.019701134Z I1024 14:08:20.019627       1 schedule_one.go:1055] "Unable to schedule pod; no fit; waiting" pod="openshift-route-controller-manager/route-controller-manager-5486b44d46-22bql" err="0/6 nodes are available: 3 node(s) didn't match Pod's node affinity/selector, 3 node(s) didn't match pod anti-affinity rules. preemption: 0/6 nodes are available: 3 Preemption is not helpful for scheduling, 3 node(s) didn't match pod anti-affinity rules."
2024-10-24T14:08:20.465977365Z I1024 14:08:20.465914       1 schedule_one.go:1055] "Unable to schedule pod; no fit; waiting" pod="openshift-console/console-bf6f6f7f6-lk9bc" err="0/6 nodes are available: 3 node(s) didn't match Pod's node affinity/selector, 3 node(s) didn't match pod anti-affinity rules. preemption: 0/6 nodes are available: 3 Preemption is not helpful for scheduling, 3 node(s) didn't match pod anti-affinity rules."
2024-10-24T14:08:20.466687564Z I1024 14:08:20.466646       1 schedule_one.go:1055] "Unable to schedule pod; no fit; waiting" pod="openshift-console/console-bf6f6f7f6-bl5sv" err="0/6 nodes are available: 3 node(s) didn't match Pod's node affinity/selector, 3 node(s) didn't match pod anti-affinity rules. preemption: 0/6 nodes are available: 3 Preemption is not helpful for scheduling, 3 node(s) didn't match pod anti-affinity rules."
2024-10-24T14:08:21.106954025Z I1024 14:08:21.106875       1 schedule_one.go:314] "Successfully bound pod to node" pod="openshift-route-controller-manager/route-controller-manager-5486b44d46-22bql" node="ci-op-2fcpj5j6-f6035-2lklf-master-1" evaluatedNodes=6 feasibleNodes=1
2024-10-24T14:08:21.980392865Z I1024 14:08:21.980305       1 schedule_one.go:1055] "Unable to schedule pod; no fit; waiting" pod="openshift-authentication/oauth-openshift-74c78cc4c7-nk55v" err="0/6 nodes are available: 3 node(s) didn't match Pod's node affinity/selector, 3 node(s) didn't match pod anti-affinity rules. preemption: 0/6 nodes are available: 3 Preemption is not helpful for scheduling, 3 node(s) didn't match pod anti-affinity rules."
2024-10-24T14:08:23.115917096Z I1024 14:08:23.115818       1 schedule_one.go:314] "Successfully bound pod to node" pod="openshift-authentication/oauth-openshift-74c78cc4c7-nk55v" node="ci-op-2fcpj5j6-f6035-2lklf-master-2" evaluatedNodes=6 feasibleNodes=1
2024-10-24T14:08:23.144783905Z I1024 14:08:23.144653       1 schedule_one.go:1055] "Unable to schedule pod; no fit; waiting" pod="openshift-route-controller-manager/route-controller-manager-5486b44d46-rqg9k" err="0/6 nodes are available: 3 node(s) didn't match Pod's node affinity/selector, 3 node(s) didn't match pod anti-affinity rules. preemption: 0/6 nodes are available: 3 Preemption is not helpful for scheduling, 3 node(s) didn't match pod anti-affinity rules."
2024-10-24T14:08:24.999057052Z I1024 14:08:24.998963       1 schedule_one.go:314] "Successfully bound pod to node" pod="openshift-marketplace/redhat-operators-cwhdg" node="ci-op-2fcpj5j6-f6035-2lklf-master-0" evaluatedNodes=6 feasibleNodes=3
2024-10-24T14:08:25.099040992Z I1024 14:08:25.098984       1 schedule_one.go:1055] "Unable to schedule pod; no fit; waiting" pod="openshift-console/console-bf6f6f7f6-bl5sv" err="0/6 nodes are available: 3 node(s) didn't match Pod's node affinity/selector, 3 node(s) didn't match pod anti-affinity rules. preemption: 0/6 nodes are available: 3 Preemption is not helpful for scheduling, 3 node(s) didn't match pod anti-affinity rules."
2024-10-24T14:08:25.115572982Z I1024 14:08:25.115487       1 schedule_one.go:314] "Successfully bound pod to node" pod="openshift-route-controller-manager/route-controller-manager-5486b44d46-rqg9k" node="ci-op-2fcpj5j6-f6035-2lklf-master-0" evaluatedNodes=6 feasibleNodes=1
2024-10-24T14:08:25.122242043Z I1024 14:08:25.122175       1 schedule_one.go:314] "Successfully bound pod to node" pod="openshift-console/console-bf6f6f7f6-lk9bc" node="ci-op-2fcpj5j6-f6035-2lklf-master-0" evaluatedNodes=6 feasibleNodes=1
2024-10-24T14:08:25.138337122Z I1024 14:08:25.138253       1 schedule_one.go:1055] "Unable to schedule pod; no fit; waiting" pod="openshift-authentication/oauth-openshift-74c78cc4c7-t6vbt" err="0/6 nodes are available: 3 node(s) didn't match Pod's node affinity/selector, 3 node(s) didn't match pod anti-affinity rules. preemption: 0/6 nodes are available: 3 Preemption is not helpful for scheduling, 3 node(s) didn't match pod anti-affinity rules."
2024-10-24T14:08:34.402695999Z I1024 14:08:34.402611       1 schedule_one.go:1055] "Unable to schedule pod; no fit; waiting" pod="openshift-authentication/oauth-openshift-74c78cc4c7-t6vbt" err="0/6 nodes are available: 3 node(s) didn't match Pod's node affinity/selector, 3 node(s) didn't match pod anti-affinity rules. preemption: 0/6 nodes are available: 3 Preemption is not helpful for scheduling, 3 node(s) didn't match pod anti-affinity rules."
2024-10-24T14:08:34.416444149Z I1024 14:08:34.416336       1 schedule_one.go:314] "Successfully bound pod to node" pod="openshift-console/console-bf6f6f7f6-bl5sv" node="ci-op-2fcpj5j6-f6035-2lklf-master-2" evaluatedNodes=6 feasibleNodes=1
2024-10-24T14:08:38.308549318Z I1024 14:08:38.308423       1 schedule_one.go:1055] "Unable to schedule pod; no fit; waiting" pod="openshift-authentication/oauth-openshift-74c78cc4c7-t6vbt" err="0/6 nodes are available: 3 node(s) didn't match Pod's node affinity/selector, 3 node(s) didn't match pod anti-affinity rules. preemption: 0/6 nodes are available: 3 Preemption is not helpful for scheduling, 3 node(s) didn't match pod anti-affinity rules."
2024-10-24T14:08:43.114921164Z I1024 14:08:43.114834       1 schedule_one.go:1055] "Unable to schedule pod; no fit; waiting" pod="openshift-authentication/oauth-openshift-74c78cc4c7-t6vbt" err="0/6 nodes are available: 3 node(s) didn't match Pod's node affinity/selector, 3 node(s) didn't match pod anti-affinity rules. preemption: 0/6 nodes are available: 3 Preemption is not helpful for scheduling, 3 node(s) didn't match pod anti-affinity rules."
2024-10-24T14:08:51.132492181Z I1024 14:08:51.132035       1 schedule_one.go:314] "Successfully bound pod to node" pod="openshift-authentication/oauth-openshift-74c78cc4c7-t6vbt" node="ci-op-2fcpj5j6-f6035-2lklf-master-1" evaluatedNodes=6 feasibleNodes=1
2024-10-24T14:08:51.541028710Z I1024 14:08:51.540964       1 schedule_one.go:314] "Successfully bound pod to node" pod="openshift-marketplace/certified-operators-wnhvq" node="ci-op-2fcpj5j6-f6035-2lklf-master-0" evaluatedNodes=6 feasibleNodes=3
2024-10-24T14:08:52.844882386Z I1024 14:08:52.844736       1 schedule_one.go:1055] "Unable to schedule pod; no fit; waiting" pod="openshift-authentication/oauth-openshift-74c78cc4c7-qwdfr" err="0/6 nodes are available: 3 node(s) didn't match Pod's node affinity/selector, 3 node(s) didn't match pod anti-affinity rules. preemption: 0/6 nodes are available: 3 Preemption is not helpful for scheduling, 3 node(s) didn't match pod anti-affinity rules."
2024-10-24T14:09:01.786445839Z I1024 14:09:01.786330       1 schedule_one.go:1055] "Unable to schedule pod; no fit; waiting" pod="openshift-authentication/oauth-openshift-74c78cc4c7-qwdfr" err="0/6 nodes are available: 3 node(s) didn't match Pod's node affinity/selector, 3 node(s) didn't match pod anti-affinity rules. preemption: 0/6 nodes are available: 3 Preemption is not helpful for scheduling, 3 node(s) didn't match pod anti-affinity rules."
2024-10-24T14:09:13.237930736Z I1024 14:09:13.237854       1 schedule_one.go:1055] "Unable to schedule pod; no fit; waiting" pod="openshift-oauth-apiserver/apiserver-58d4d69dd7-f2th2" err="0/6 nodes are available: 3 node(s) didn't match Pod's node affinity/selector, 3 node(s) didn't match pod anti-affinity rules. preemption: 0/6 nodes are available: 3 Preemption is not helpful for scheduling, 3 node(s) didn't match pod anti-affinity rules."
2024-10-24T14:09:18.243980761Z I1024 14:09:18.243899       1 schedule_one.go:1055] "Unable to schedule pod; no fit; waiting" pod="openshift-oauth-apiserver/apiserver-58d4d69dd7-f2th2" err="0/6 nodes are available: 3 node(s) didn't match Pod's node affinity/selector, 3 node(s) didn't match pod anti-affinity rules. preemption: 0/6 nodes are available: 3 Preemption is not helpful for scheduling, 3 node(s) didn't match pod anti-affinity rules."
2024-10-24T14:09:18.259716251Z I1024 14:09:18.259098       1 schedule_one.go:314] "Successfully bound pod to node" pod="openshift-authentication/oauth-openshift-74c78cc4c7-qwdfr" node="ci-op-2fcpj5j6-f6035-2lklf-master-0" evaluatedNodes=6 feasibleNodes=1
2024-10-24T14:09:33.416900056Z I1024 14:09:33.416814       1 schedule_one.go:1055] "Unable to schedule pod; no fit; waiting" pod="openshift-oauth-apiserver/apiserver-586d87f8b7-xg64h" err="0/6 nodes are available: 3 node(s) didn't match Pod's node affinity/selector, 3 node(s) didn't match pod anti-affinity rules. preemption: 0/6 nodes are available: 3 Preemption is not helpful for scheduling, 3 node(s) didn't match pod anti-affinity rules."
2024-10-24T14:09:57.250986066Z I1024 14:09:57.250901       1 schedule_one.go:1055] "Unable to schedule pod; no fit; waiting" pod="openshift-oauth-apiserver/apiserver-6d668d4fc7-pn5rk" err="0/6 nodes are available: 3 node(s) didn't match Pod's node affinity/selector, 3 node(s) didn't match pod anti-affinity rules. preemption: 0/6 nodes are available: 3 Preemption is not helpful for scheduling, 3 node(s) didn't match pod anti-affinity rules."
2024-10-24T14:09:58.361488103Z I1024 14:09:58.361431       1 schedule_one.go:1055] "Unable to schedule pod; no fit; waiting" pod="openshift-oauth-apiserver/apiserver-6d668d4fc7-pn5rk" err="0/6 nodes are available: 3 node(s) didn't match Pod's node affinity/selector, 3 node(s) didn't match pod anti-affinity rules. preemption: 0/6 nodes are available: 3 Preemption is not helpful for scheduling, 3 node(s) didn't match pod anti-affinity rules."
2024-10-24T14:10:05.606144752Z I1024 14:10:05.606048       1 schedule_one.go:314] "Successfully bound pod to node" pod="openshift-oauth-apiserver/apiserver-6d668d4fc7-pn5rk" node="ci-op-2fcpj5j6-f6035-2lklf-master-2" evaluatedNodes=6 feasibleNodes=1
2024-10-24T14:11:57.289468558Z I1024 14:11:57.289387       1 schedule_one.go:314] "Successfully bound pod to node" pod="openshift-marketplace/redhat-marketplace-dfq7f" node="ci-op-2fcpj5j6-f6035-2lklf-master-2" evaluatedNodes=6 feasibleNodes=3
2024-10-24T14:14:35.671143135Z I1024 14:14:35.670296       1 schedule_one.go:314] "Successfully bound pod to node" pod="openshift-marketplace/community-operators-9z5nm" node="ci-op-2fcpj5j6-f6035-2lklf-master-2" evaluatedNodes=6 feasibleNodes=3
2024-10-24T14:15:00.162572341Z I1024 14:15:00.162465       1 schedule_one.go:314] "Successfully bound pod to node" pod="openshift-operator-lifecycle-manager/collect-profiles-28829655-d7dgm" node="ci-op-2fcpj5j6-f6035-2lklf-worker-a-8hj4x" evaluatedNodes=6 feasibleNodes=3
2024-10-24T14:20:54.967578742Z I1024 14:20:54.967366       1 schedule_one.go:314] "Successfully bound pod to node" pod="openshift-marketplace/redhat-operators-drwtw" node="ci-op-2fcpj5j6-f6035-2lklf-master-0" evaluatedNodes=6 feasibleNodes=3
2024-10-24T14:23:04.293492319Z I1024 14:23:04.293391       1 schedule_one.go:314] "Successfully bound pod to node" pod="openshift-marketplace/certified-operators-fbht5" node="ci-op-2fcpj5j6-f6035-2lklf-master-0" evaluatedNodes=6 feasibleNodes=3
2024-10-24T14:23:08.639200342Z I1024 14:23:08.639129       1 schedule_one.go:314] "Successfully bound pod to node" pod="openshift-marketplace/redhat-marketplace-hhxmm" node="ci-op-2fcpj5j6-f6035-2lklf-master-2" evaluatedNodes=6 feasibleNodes=3
2024-10-24T14:24:58.631175688Z I1024 14:24:58.631086       1 schedule_one.go:314] "Successfully bound pod to node" pod="openshift-marketplace/community-operators-m42qg" node="ci-op-2fcpj5j6-f6035-2lklf-master-2" evaluatedNodes=6 feasibleNodes=3
2024-10-24T14:30:00.168401655Z I1024 14:30:00.168300       1 schedule_one.go:314] "Successfully bound pod to node" pod="openshift-operator-lifecycle-manager/collect-profiles-28829670-8jp8p" node="ci-op-2fcpj5j6-f6035-2lklf-worker-a-8hj4x" evaluatedNodes=6 feasibleNodes=3
2024-10-24T14:31:43.747382046Z I1024 14:31:43.747297       1 schedule_one.go:314] "Successfully bound pod to node" pod="openshift-marketplace/redhat-operators-pppfb" node="ci-op-2fcpj5j6-f6035-2lklf-master-0" evaluatedNodes=6 feasibleNodes=3
2024-10-24T14:33:41.025190418Z I1024 14:33:41.025118       1 schedule_one.go:314] "Successfully bound pod to node" pod="openshift-marketplace/redhat-marketplace-h5n44" node="ci-op-2fcpj5j6-f6035-2lklf-master-2" evaluatedNodes=6 feasibleNodes=3
2024-10-24T14:35:32.946470677Z I1024 14:35:32.946402       1 schedule_one.go:314] "Successfully bound pod to node" pod="openshift-marketplace/certified-operators-gh6hl" node="ci-op-2fcpj5j6-f6035-2lklf-master-0" evaluatedNodes=6 feasibleNodes=3
2024-10-24T14:35:35.128533514Z I1024 14:35:35.128450       1 schedule_one.go:314] "Successfully bound pod to node" pod="openshift-marketplace/community-operators-24v2d" node="ci-op-2fcpj5j6-f6035-2lklf-master-2" evaluatedNodes=6 feasibleNodes=3
2024-10-24T14:42:19.732814355Z I1024 14:42:19.728989       1 tlsconfig.go:181] "Loaded client CA" index=0 certName="client-ca::kube-system::extension-apiserver-authentication::client-ca-file,client-ca::kube-system::extension-apiserver-authentication::requestheader-client-ca-file" certDetail="\"admin-kubeconfig-signer\" [] issuer=\"<self>\" (2024-10-24 12:49:31 +0000 UTC to 2034-10-22 12:49:31 +0000 UTC (now=2024-10-24 14:42:19.728701225 +0000 UTC))"
2024-10-24T14:42:19.732814355Z I1024 14:42:19.729109       1 tlsconfig.go:181] "Loaded client CA" index=1 certName="client-ca::kube-system::extension-apiserver-authentication::client-ca-file,client-ca::kube-system::extension-apiserver-authentication::requestheader-client-ca-file" certDetail="\"kubelet-signer\" [] issuer=\"<self>\" (2024-10-24 12:49:34 +0000 UTC to 2024-10-25 12:49:34 +0000 UTC (now=2024-10-24 14:42:19.729098165 +0000 UTC))"
2024-10-24T14:42:19.732814355Z I1024 14:42:19.729132       1 tlsconfig.go:181] "Loaded client CA" index=2 certName="client-ca::kube-system::extension-apiserver-authentication::client-ca-file,client-ca::kube-system::extension-apiserver-authentication::requestheader-client-ca-file" certDetail="\"kube-control-plane-signer\" [] issuer=\"<self>\" (2024-10-24 12:49:34 +0000 UTC to 2025-10-24 12:49:34 +0000 UTC (now=2024-10-24 14:42:19.729125875 +0000 UTC))"
2024-10-24T14:42:19.732814355Z I1024 14:42:19.729149       1 tlsconfig.go:181] "Loaded client CA" index=3 certName="client-ca::kube-system::extension-apiserver-authentication::client-ca-file,client-ca::kube-system::extension-apiserver-authentication::requestheader-client-ca-file" certDetail="\"kube-apiserver-to-kubelet-signer\" [] issuer=\"<self>\" (2024-10-24 12:49:34 +0000 UTC to 2025-10-24 12:49:34 +0000 UTC (now=2024-10-24 14:42:19.729143755 +0000 UTC))"
2024-10-24T14:42:19.732814355Z I1024 14:42:19.729193       1 tlsconfig.go:181] "Loaded client CA" index=4 certName="client-ca::kube-system::extension-apiserver-authentication::client-ca-file,client-ca::kube-system::extension-apiserver-authentication::requestheader-client-ca-file" certDetail="\"kubelet-bootstrap-kubeconfig-signer\" [] issuer=\"<self>\" (2024-10-24 12:49:32 +0000 UTC to 2034-10-22 12:49:32 +0000 UTC (now=2024-10-24 14:42:19.729185555 +0000 UTC))"
2024-10-24T14:42:19.732814355Z I1024 14:42:19.729217       1 tlsconfig.go:181] "Loaded client CA" index=5 certName="client-ca::kube-system::extension-apiserver-authentication::client-ca-file,client-ca::kube-system::extension-apiserver-authentication::requestheader-client-ca-file" certDetail="\"kube-csr-signer_@1729775012\" [] issuer=\"kubelet-signer\" (2024-10-24 13:03:31 +0000 UTC to 2024-10-25 12:49:34 +0000 UTC (now=2024-10-24 14:42:19.729208015 +0000 UTC))"
2024-10-24T14:42:19.732814355Z I1024 14:42:19.729236       1 tlsconfig.go:181] "Loaded client CA" index=6 certName="client-ca::kube-system::extension-apiserver-authentication::client-ca-file,client-ca::kube-system::extension-apiserver-authentication::requestheader-client-ca-file" certDetail="\"openshift-kube-apiserver-operator_node-system-admin-signer@1729775011\" [] issuer=\"<self>\" (2024-10-24 13:03:30 +0000 UTC to 2025-10-24 13:03:31 +0000 UTC (now=2024-10-24 14:42:19.729229755 +0000 UTC))"
2024-10-24T14:42:19.732814355Z I1024 14:42:19.729282       1 tlsconfig.go:181] "Loaded client CA" index=7 certName="client-ca::kube-system::extension-apiserver-authentication::client-ca-file,client-ca::kube-system::extension-apiserver-authentication::requestheader-client-ca-file" certDetail="\"TestUserClientCABundleRootCA_3120422217834922768\" [] issuer=\"<self>\" (2023-10-24 14:42:09 +0000 UTC to 2025-10-24 14:42:09 +0000 UTC (now=2024-10-24 14:42:19.729274175 +0000 UTC))"
2024-10-24T14:42:19.732814355Z I1024 14:42:19.729300       1 tlsconfig.go:181] "Loaded client CA" index=8 certName="client-ca::kube-system::extension-apiserver-authentication::client-ca-file,client-ca::kube-system::extension-apiserver-authentication::requestheader-client-ca-file" certDetail="\"aggregator-signer\" [] issuer=\"<self>\" (2024-10-24 12:49:32 +0000 UTC to 2024-10-25 12:49:32 +0000 UTC (now=2024-10-24 14:42:19.729294915 +0000 UTC))"
2024-10-24T14:42:19.732814355Z I1024 14:42:19.729321       1 tlsconfig.go:181] "Loaded client CA" index=9 certName="client-ca::kube-system::extension-apiserver-authentication::client-ca-file,client-ca::kube-system::extension-apiserver-authentication::requestheader-client-ca-file" certDetail="\"openshift-kube-apiserver-operator_aggregator-client-signer@1729777579\" [] issuer=\"<self>\" (2024-10-24 13:46:18 +0000 UTC to 2024-10-25 01:46:19 +0000 UTC (now=2024-10-24 14:42:19.729314755 +0000 UTC))"
2024-10-24T14:42:19.732814355Z I1024 14:42:19.729581       1 tlsconfig.go:203] "Loaded serving cert" certName="serving-cert::/etc/kubernetes/static-pod-resources/secrets/serving-cert/tls.crt::/etc/kubernetes/static-pod-resources/secrets/serving-cert/tls.key" certDetail="\"scheduler.openshift-kube-scheduler.svc\" [serving] validServingFor=[scheduler.openshift-kube-scheduler.svc,scheduler.openshift-kube-scheduler.svc.cluster.local] issuer=\"openshift-service-serving-signer@1729775010\" (2024-10-24 13:03:41 +0000 UTC to 2026-10-24 13:03:42 +0000 UTC (now=2024-10-24 14:42:19.729568855 +0000 UTC))"
2024-10-24T14:42:19.732814355Z I1024 14:42:19.729980       1 named_certificates.go:53] "Loaded SNI cert" index=0 certName="self-signed loopback" certDetail="\"apiserver-loopback-client@1729776686\" [serving] validServingFor=[apiserver-loopback-client] issuer=\"apiserver-loopback-client-ca@1729776685\" (2024-10-24 12:31:25 +0000 UTC to 2025-10-24 12:31:25 +0000 UTC (now=2024-10-24 14:42:19.729961705 +0000 UTC))"
2024-10-24T14:42:23.984828529Z I1024 14:42:23.984650       1 schedule_one.go:314] "Successfully bound pod to node" pod="openshift-marketplace/redhat-operators-vn4tl" node="ci-op-2fcpj5j6-f6035-2lklf-master-0" evaluatedNodes=6 feasibleNodes=3
2024-10-24T14:42:31.667568464Z I1024 14:42:31.667491       1 schedule_one.go:1055] "Unable to schedule pod; no fit; waiting" pod="openshift-oauth-apiserver/apiserver-7b485d54c8-xf6hd" err="0/6 nodes are available: 3 node(s) didn't match Pod's node affinity/selector, 3 node(s) didn't match pod anti-affinity rules. preemption: 0/6 nodes are available: 3 Preemption is not helpful for scheduling, 3 node(s) didn't match pod anti-affinity rules."
2024-10-24T14:42:33.431480753Z I1024 14:42:33.431385       1 schedule_one.go:1055] "Unable to schedule pod; no fit; waiting" pod="openshift-oauth-apiserver/apiserver-7b485d54c8-xf6hd" err="0/6 nodes are available: 3 node(s) didn't match Pod's node affinity/selector, 3 node(s) didn't match pod anti-affinity rules. preemption: 0/6 nodes are available: 3 Preemption is not helpful for scheduling, 3 node(s) didn't match pod anti-affinity rules."
2024-10-24T14:42:36.765571174Z I1024 14:42:36.765484       1 schedule_one.go:314] "Successfully bound pod to node" pod="openshift-monitoring/metrics-server-5ffb7997c-2fmcw" node="ci-op-2fcpj5j6-f6035-2lklf-worker-b-hj8l2" evaluatedNodes=6 feasibleNodes=1
2024-10-24T14:42:36.815453863Z I1024 14:42:36.815354       1 schedule_one.go:1055] "Unable to schedule pod; no fit; waiting" pod="openshift-monitoring/metrics-server-5ffb7997c-krp7q" err="0/6 nodes are available: 3 node(s) didn't match pod anti-affinity rules, 3 node(s) had untolerated taint {node-role.kubernetes.io/master: }. preemption: 0/6 nodes are available: 3 Preemption is not helpful for scheduling, 3 node(s) didn't match pod anti-affinity rules."
2024-10-24T14:42:36.838105243Z I1024 14:42:36.838031       1 schedule_one.go:1055] "Unable to schedule pod; no fit; waiting" pod="openshift-oauth-apiserver/apiserver-7b485d54c8-xf6hd" err="0/6 nodes are available: 3 node(s) didn't match Pod's node affinity/selector, 3 node(s) didn't match pod anti-affinity rules. preemption: 0/6 nodes are available: 3 Preemption is not helpful for scheduling, 3 node(s) didn't match pod anti-affinity rules."
2024-10-24T14:42:38.434546043Z I1024 14:42:38.434459       1 schedule_one.go:1055] "Unable to schedule pod; no fit; waiting" pod="openshift-monitoring/metrics-server-5ffb7997c-krp7q" err="0/6 nodes are available: 3 node(s) didn't match pod anti-affinity rules, 3 node(s) had untolerated taint {node-role.kubernetes.io/master: }. preemption: 0/6 nodes are available: 3 Preemption is not helpful for scheduling, 3 node(s) didn't match pod anti-affinity rules."
2024-10-24T14:42:40.366249262Z I1024 14:42:40.366166       1 schedule_one.go:1055] "Unable to schedule pod; no fit; waiting" pod="openshift-authentication/oauth-openshift-9958d4595-s94mv" err="0/6 nodes are available: 3 node(s) didn't match Pod's node affinity/selector, 3 node(s) didn't match pod anti-affinity rules. preemption: 0/6 nodes are available: 3 Preemption is not helpful for scheduling, 3 node(s) didn't match pod anti-affinity rules."
2024-10-24T14:42:40.761566400Z I1024 14:42:40.761474       1 schedule_one.go:1055] "Unable to schedule pod; no fit; waiting" pod="openshift-oauth-apiserver/apiserver-6d668d4fc7-hfkd9" err="0/6 nodes are available: 3 node(s) didn't match Pod's node affinity/selector, 3 node(s) didn't match pod anti-affinity rules. preemption: 0/6 nodes are available: 3 Preemption is not helpful for scheduling, 3 node(s) didn't match pod anti-affinity rules."
2024-10-24T14:42:41.434997236Z I1024 14:42:41.434909       1 schedule_one.go:1055] "Unable to schedule pod; no fit; waiting" pod="openshift-monitoring/metrics-server-5ffb7997c-krp7q" err="0/6 nodes are available: 3 node(s) didn't match pod anti-affinity rules, 3 node(s) had untolerated taint {node-role.kubernetes.io/master: }. preemption: 0/6 nodes are available: 3 Preemption is not helpful for scheduling, 3 node(s) didn't match pod anti-affinity rules."
2024-10-24T14:42:52.961122037Z I1024 14:42:52.960744       1 schedule_one.go:1055] "Unable to schedule pod; no fit; waiting" pod="openshift-authentication/oauth-openshift-66d787f86d-ln9xx" err="0/6 nodes are available: 3 node(s) didn't match Pod's node affinity/selector, 3 node(s) didn't match pod anti-affinity rules. preemption: 0/6 nodes are available: 3 Preemption is not helpful for scheduling, 3 node(s) didn't match pod anti-affinity rules."
2024-10-24T14:43:05.773688781Z I1024 14:43:05.773573       1 schedule_one.go:1055] "Unable to schedule pod; no fit; waiting" pod="openshift-oauth-apiserver/apiserver-6d668d4fc7-hfkd9" err="0/6 nodes are available: 3 node(s) didn't match Pod's node affinity/selector, 3 node(s) didn't match pod anti-affinity rules. preemption: 0/6 nodes are available: 3 Preemption is not helpful for scheduling, 3 node(s) didn't match pod anti-affinity rules."
2024-10-24T14:43:05.774404671Z I1024 14:43:05.774327       1 schedule_one.go:1055] "Unable to schedule pod; no fit; waiting" pod="openshift-monitoring/metrics-server-5ffb7997c-krp7q" err="0/6 nodes are available: 3 node(s) didn't match pod anti-affinity rules, 3 node(s) had untolerated taint {node-role.kubernetes.io/master: }. preemption: 0/6 nodes are available: 3 Preemption is not helpful for scheduling, 3 node(s) didn't match pod anti-affinity rules."
2024-10-24T14:43:05.798281561Z I1024 14:43:05.798216       1 schedule_one.go:314] "Successfully bound pod to node" pod="openshift-authentication/oauth-openshift-66d787f86d-ln9xx" node="ci-op-2fcpj5j6-f6035-2lklf-master-0" evaluatedNodes=6 feasibleNodes=1
2024-10-24T14:43:07.778457399Z I1024 14:43:07.778373       1 schedule_one.go:1055] "Unable to schedule pod; no fit; waiting" pod="openshift-authentication/oauth-openshift-66d787f86d-n8zks" err="0/6 nodes are available: 3 node(s) didn't match Pod's node affinity/selector, 3 node(s) didn't match pod anti-affinity rules. preemption: 0/6 nodes are available: 3 Preemption is not helpful for scheduling, 3 node(s) didn't match pod anti-affinity rules."
2024-10-24T14:43:23.977572493Z I1024 14:43:23.977466       1 schedule_one.go:1055] "Unable to schedule pod; no fit; waiting" pod="openshift-monitoring/metrics-server-5ffb7997c-krp7q" err="0/6 nodes are available: 3 node(s) didn't match pod anti-affinity rules, 3 node(s) had untolerated taint {node-role.kubernetes.io/master: }. preemption: 0/6 nodes are available: 3 Preemption is not helpful for scheduling, 3 node(s) didn't match pod anti-affinity rules."
2024-10-24T14:43:23.978448272Z I1024 14:43:23.978407       1 schedule_one.go:1055] "Unable to schedule pod; no fit; waiting" pod="openshift-authentication/oauth-openshift-66d787f86d-n8zks" err="0/6 nodes are available: 3 node(s) didn't match Pod's node affinity/selector, 3 node(s) didn't match pod anti-affinity rules. preemption: 0/6 nodes are available: 3 Preemption is not helpful for scheduling, 3 node(s) didn't match pod anti-affinity rules."
2024-10-24T14:43:23.990193093Z I1024 14:43:23.990071       1 schedule_one.go:314] "Successfully bound pod to node" pod="openshift-oauth-apiserver/apiserver-6d668d4fc7-hfkd9" node="ci-op-2fcpj5j6-f6035-2lklf-master-2" evaluatedNodes=6 feasibleNodes=1
2024-10-24T14:43:28.808848524Z I1024 14:43:28.808779       1 schedule_one.go:314] "Successfully bound pod to node" pod="openshift-must-gather-b8249/must-gather-w6j9g" node="ci-op-2fcpj5j6-f6035-2lklf-master-0" evaluatedNodes=6 feasibleNodes=3
2024-10-24T14:43:30.006451747Z I1024 14:43:30.006352       1 schedule_one.go:1055] "Unable to schedule pod; no fit; waiting" pod="openshift-authentication/oauth-openshift-66d787f86d-n8zks" err="0/6 nodes are available: 3 node(s) didn't match Pod's node affinity/selector, 3 node(s) didn't match pod anti-affinity rules. preemption: 0/6 nodes are available: 3 Preemption is not helpful for scheduling, 3 node(s) didn't match pod anti-affinity rules."
2024-10-24T14:43:34.464416281Z I1024 14:43:34.464337       1 schedule_one.go:1055] "Unable to schedule pod; no fit; waiting" pod="openshift-monitoring/metrics-server-5ffb7997c-krp7q" err="0/6 nodes are available: 3 node(s) didn't match pod anti-affinity rules, 3 node(s) had untolerated taint {node-role.kubernetes.io/master: }. preemption: 0/6 nodes are available: 3 Preemption is not helpful for scheduling, 3 node(s) didn't match pod anti-affinity rules."
2024-10-24T14:43:34.478839680Z I1024 14:43:34.478713       1 schedule_one.go:314] "Successfully bound pod to node" pod="openshift-authentication/oauth-openshift-66d787f86d-n8zks" node="ci-op-2fcpj5j6-f6035-2lklf-master-1" evaluatedNodes=6 feasibleNodes=1
2024-10-24T14:43:36.536618848Z I1024 14:43:36.536538       1 schedule_one.go:1055] "Unable to schedule pod; no fit; waiting" pod="openshift-authentication/oauth-openshift-66d787f86d-9frbd" err="0/6 nodes are available: 3 node(s) didn't match Pod's node affinity/selector, 3 node(s) didn't match pod anti-affinity rules. preemption: 0/6 nodes are available: 3 Preemption is not helpful for scheduling, 3 node(s) didn't match pod anti-affinity rules."
2024-10-24T14:43:39.261543192Z I1024 14:43:39.261469       1 schedule_one.go:1055] "Unable to schedule pod; no fit; waiting" pod="openshift-authentication/oauth-openshift-66d787f86d-9frbd" err="0/6 nodes are available: 3 node(s) didn't match Pod's node affinity/selector, 3 node(s) didn't match pod anti-affinity rules. preemption: 0/6 nodes are available: 3 Preemption is not helpful for scheduling, 3 node(s) didn't match pod anti-affinity rules."
2024-10-24T14:43:44.470119931Z I1024 14:43:44.470039       1 schedule_one.go:1055] "Unable to schedule pod; no fit; waiting" pod="openshift-monitoring/metrics-server-5ffb7997c-krp7q" err="0/6 nodes are available: 3 node(s) didn't match pod anti-affinity rules, 3 node(s) had untolerated taint {node-role.kubernetes.io/master: }. preemption: 0/6 nodes are available: 3 Preemption is not helpful for scheduling, 3 node(s) didn't match pod anti-affinity rules."
2024-10-24T14:43:46.028114042Z I1024 14:43:46.028017       1 schedule_one.go:314] "Successfully bound pod to node" pod="openshift-must-gather-b8249/perf-node-gather-daemonset-74jhk" node="ci-op-2fcpj5j6-f6035-2lklf-master-0" evaluatedNodes=1 feasibleNodes=1
2024-10-24T14:43:46.034475832Z I1024 14:43:46.034403       1 schedule_one.go:314] "Successfully bound pod to node" pod="openshift-must-gather-b8249/perf-node-gather-daemonset-xbt74" node="ci-op-2fcpj5j6-f6035-2lklf-master-2" evaluatedNodes=1 feasibleNodes=1
2024-10-24T14:43:46.034475832Z I1024 14:43:46.034399       1 schedule_one.go:314] "Successfully bound pod to node" pod="openshift-must-gather-b8249/perf-node-gather-daemonset-x2pdp" node="ci-op-2fcpj5j6-f6035-2lklf-master-1" evaluatedNodes=1 feasibleNodes=1
2024-10-24T14:43:46.096275441Z I1024 14:43:46.095225       1 schedule_one.go:314] "Successfully bound pod to node" pod="openshift-must-gather-b8249/perf-node-gather-daemonset-6pph4" node="ci-op-2fcpj5j6-f6035-2lklf-worker-c-z8hfz" evaluatedNodes=1 feasibleNodes=1
2024-10-24T14:43:46.096275441Z I1024 14:43:46.095429       1 schedule_one.go:314] "Successfully bound pod to node" pod="openshift-must-gather-b8249/perf-node-gather-daemonset-kfnjp" node="ci-op-2fcpj5j6-f6035-2lklf-worker-b-hj8l2" evaluatedNodes=1 feasibleNodes=1
2024-10-24T14:43:46.120291981Z I1024 14:43:46.120223       1 schedule_one.go:314] "Successfully bound pod to node" pod="openshift-must-gather-b8249/perf-node-gather-daemonset-k26sv" node="ci-op-2fcpj5j6-f6035-2lklf-worker-a-8hj4x" evaluatedNodes=1 feasibleNodes=1
2024-10-24T14:43:57.156645645Z I1024 14:43:57.156574       1 schedule_one.go:314] "Successfully bound pod to node" pod="openshift-marketplace/redhat-marketplace-zpgfj" node="ci-op-2fcpj5j6-f6035-2lklf-master-2" evaluatedNodes=6 feasibleNodes=3
2024-10-24T14:44:01.901968317Z I1024 14:44:01.901901       1 schedule_one.go:1055] "Unable to schedule pod; no fit; waiting" pod="openshift-monitoring/metrics-server-5ffb7997c-krp7q" err="0/6 nodes are available: 3 node(s) didn't match pod anti-affinity rules, 3 node(s) had untolerated taint {node-role.kubernetes.io/master: }. preemption: 0/6 nodes are available: 3 Preemption is not helpful for scheduling, 3 node(s) didn't match pod anti-affinity rules."
2024-10-24T14:44:01.914037757Z I1024 14:44:01.913970       1 schedule_one.go:314] "Successfully bound pod to node" pod="openshift-authentication/oauth-openshift-66d787f86d-9frbd" node="ci-op-2fcpj5j6-f6035-2lklf-master-2" evaluatedNodes=6 feasibleNodes=1
2024-10-24T14:44:12.487089534Z I1024 14:44:12.487015       1 schedule_one.go:1055] "Unable to schedule pod; no fit; waiting" pod="openshift-monitoring/metrics-server-5ffb7997c-krp7q" err="0/6 nodes are available: 3 node(s) didn't match pod anti-affinity rules, 3 node(s) had untolerated taint {node-role.kubernetes.io/master: }. preemption: 0/6 nodes are available: 3 Preemption is not helpful for scheduling, 3 node(s) didn't match pod anti-affinity rules."
2024-10-24T14:44:22.492712724Z I1024 14:44:22.492639       1 schedule_one.go:1055] "Unable to schedule pod; no fit; waiting" pod="openshift-monitoring/metrics-server-5ffb7997c-krp7q" err="0/6 nodes are available: 3 node(s) didn't match pod anti-affinity rules, 3 node(s) had untolerated taint {node-role.kubernetes.io/master: }. preemption: 0/6 nodes are available: 3 Preemption is not helpful for scheduling, 3 node(s) didn't match pod anti-affinity rules."
